Workbook
Name pacul_05_05_2021: 'Get External'!#REF!

Sheet Get External

Sheet STOK PACUL
A1: NoItemCOPY | B1: RakBarang | C1: NoItem | D1: NamaItem | E1: Quantity | F1: NOTE | G1: STS | H1: SO+BR DTG | I1: CATATAN
A2: - | B2: NOSTOK | C2: - | D2: - | E2: 0 | H2: =E2+SUMIF('BR DTG PACUL'!C:C,'STOK PACUL'!C2,'BR DTG PACUL'!E:E) -> 0 | I2: JANGAN LUPA KOLOM H COPY RUMUS SAMPAI BAWAH
A3: 011-K44-NPP PK | B3: NOSTOK | C3: 011-K44-NPP PK | D3: PISTON KIT H.BEAT/SCOOPY FI ESP NPP | E3: 0 | H3: =E3+SUMIF('BR DTG PACUL'!C:C,'STOK PACUL'!C3,'BR DTG PACUL'!E:E) -> 0
A4: 011-KPH-950-025 | B4: NOSTOK | C4: 011-KPH-950-025 | D4: RING PISTON H.KARISMA IMI | E4: 0 | H4: =E4+SUMIF('BR DTG PACUL'!C:C,'STOK PACUL'!C4,'BR DTG PACUL'!E:E) -> 0
A5: 011-KPH-NPP PK | B5: NOSTOK | C5: 011-KPH-NPP PK | D5: PISTON KIT H.KARISMA/SUPRA X 125 NPP (150) | E5: 0 | H5: =E5+SUMIF('BR DTG PACUL'!C:C,'STOK PACUL'!C5,'BR DTG PACUL'!E:E) -> 0
A6: 011-KVY-900 | B6: NOSTOK | C6: 011-KVY-900 | D6: KLEP IN-EX (SET) H.BEAT CARBU NPP (011-KVY-901) | E6: 0 | H6: =E6+SUMIF('BR DTG PACUL'!C:C,'STOK PACUL'!C6,'BR DTG PACUL'!E:E) -> 0
A7: 011-KVY-NPP PK | B7: NOSTOK | C7: 011-KVY-NPP PK | D7: PISTON KIT H.BEAT CARBU NPP | E7: 0 | H7: =E7+SUMIF('BR DTG PACUL'!C:C,'STOK PACUL'!C7,'BR DTG PACUL'!E:E) -> 0
A8: 011-KZR-NPP PK | B8: NOSTOK | C8: 011-KZR-NPP PK | D8: PISTON KIT H.VARIO 125 OS 50 NPP | E8: 0 | H8: =E8+SUMIF('BR DTG PACUL'!C:C,'STOK PACUL'!C8,'BR DTG PACUL'!E:E) -> 0
A9: 01-C21-300-40AA | B9: NOSTOK | C9: 01-C21-300-40AA | D9: BATOK DEPAN SMASH 125 WIN | E9: 0 | H9: =E9+SUMIF('BR DTG PACUL'!C:C,'STOK PACUL'!C9,'BR DTG PACUL'!E:E) -> 0
A10: 01-C21-307-40AA | B10: NOSTOK | C10: 01-C21-307-40AA | D10: SLEBOR DEPAN SMASH 125 WIN | E10: 0 | H10: =E10+SUMIF('BR DTG PACUL'!C:C,'STOK PACUL'!C10,'BR DTG PACUL'!E:E) -> 0
A11: 01-D17-706-99AA | B11: NOSTOK | C11: 01-D17-706-99AA | D11: SWITCH REM Y.JUPITER Z IMI | E11: 0 | H11: =E11+SUMIF('BR DTG PACUL'!C:C,'STOK PACUL'!C11,'BR DTG PACUL'!E:E) -> 0
A12: 01-D24-001-00AA | B12: BODYPART | C12: 01-D24-001-00AA | D12: MIKA LAMPU DEPAN Y.MIO/KACA LAMPU DEPAN MIO | E12: 1 | H12: =E12+SUMIF('BR DTG PACUL'!C:C,'STOK PACUL'!C12,'BR DTG PACUL'!E:E) -> 1
A13: 06141-GN5-505 | B13: NOSTOK | C13: 06141-GN5-505 | D13: RANTE KETENG SUPRA X | E13: 0 | H13: =E13+SUMIF('BR DTG PACUL'!C:C,'STOK PACUL'!C13,'BR DTG PACUL'!E:E) -> 0
A14: 06141-KRS-505 | B14: NOSTOK | C14: 06141-KRS-505 | D14: KETENG SET SUPRAFIT NEW | E14: 0 | H14: =E14+SUMIF('BR DTG PACUL'!C:C,'STOK PACUL'!C14,'BR DTG PACUL'!E:E) -> 0
... A80: 1110-159NS | B80: NOSTOK | C80: 1110-159NS | D80: RUJI BELAKANG KARISMA/REVO | E80: 0 | H80: =E80+SUMIF('BR DTG PACUL'!C:C,'STOK PACUL'!C80,'BR DTG PACUL'!E:E) -> 0
A81: 11103-KVB-901 | B81: NOSTOK | C81: 11103-KVB-901 | D81: KARET MONTING H.VARIO ORI | E81: 0 | F81: 11103-KVB-930 | H81: =E81+SUMIF('BR DTG PACUL'!C:C,'STOK PACUL'!C81,'BR DTG PACUL'!E:E) -> 0
A82: 11103-KVB-930 | B82: KARET & SELANG | C82: 11103-KVB-930 | D82: KARET MONTING H.VARIO ORI | E82: 2 | F82: 11103-KVB-930 | H82: =E82+SUMIF('BR DTG PACUL'!C:C,'STOK PACUL'!C82,'BR DTG PACUL'!E:E) -> 2
A83: 11108-KZL-930 | B83: NOSTOK | C83: 11108-KZL-930 | D83: PLAT KANCINGAN AS PULLY BEAT/VARIO | E83: 0 | H83: =E83+SUMIF('BR DTG PACUL'!C:C,'STOK PACUL'!C83,'BR DTG PACUL'!E:E) -> 0
A84: 1111-160 | B84: NOSTOK | C84: 1111-160 | D84: SUP RUJI 250-1 H.AHM | E84: 0 | H84: =E84+SUMIF('BR DTG PACUL'!C:C,'STOK PACUL'!C84,'BR DTG PACUL'!E:E) -> 0
A85: 1111-183 | B85: NOSTOK | C85: 1111-183 | D85: SUP/RUJI DEPAN H.SUPRA X 125 ORI | E85: 0 | H85: =E85+SUMIF('BR DTG PACUL'!C:C,'STOK PACUL'!C85,'BR DTG PACUL'!E:E) -> 0
A86: 11173-46G10-000 | B86: NOSTOK | C86: 11173-46G10-000 | D86: SEAL HEAD/KARET SILINDER HEAD S.SPIN ORI | E86: 0 | H86: =E86+SUMIF('BR DTG PACUL'!C:C,'STOK PACUL'!C86,'BR DTG PACUL'!E:E) -> 0
A87: 11203-KVB-901 | B87: NOSTOK | C87: 11203-KVB-901 | D87: KARET BAWAH SHOCK BELAKANG H.VARIO ORI | E87: 0 | H87: =E87+SUMIF('BR DTG PACUL'!C:C,'STOK PACUL'!C87,'BR DTG PACUL'!E:E) -> 0
A88: 11210B09G10N000 | B88: NOSTOK | C88: 11210B09G10N000 | D88: BLOK + PISTON S.SMASH ORI | E88: 0 | H88: =E88+SUMIF('BR DTG PACUL'!C:C,'STOK PACUL'!C88,'BR DTG PACUL'!E:E) -> 0
A89: 11361-K44-V00 | B89: NOSTOK | C89: 11361-K44-V00 | D89: TUTUP POMPA OLI BEAT/SCOOPY/ESP | E89: 0 | H89: =E89+SUMIF('BR DTG PACUL'!C:C,'STOK PACUL'!C89,'BR DTG PACUL'!E:E) -> 0
A90: 11361-KWN-901 | C90: 11361-KWN-901 | D90: PLAT DUDUKAN SPULL ASSY H.VARIO ORI | E90: 0 | H90: =E90+SUMIF('BR DTG PACUL'!C:C,'STOK PACUL'!C90,'BR DTG PACUL'!E:E) -> 0
A91: 11363-KWN-900 | B91: KARET & SELANG | C91: 11363-KWN-900 | D91: ORING MAGHNET H.VARIO 125 ORI | E91: 1 | H91: =E91+SUMIF('BR DTG PACUL'!C:C,'STOK PACUL'!C91,'BR DTG PACUL'!E:E) -> 1
A92: 11394-K56-V50 | B92: NOSTOK | C92: 11394-K56-V50 | D92: PERPAK KOPLING H.CB150R 15-18/CBR150 ORI | E92: 0 | H92: =E92+SUMIF('BR DTG PACUL'!C:C,'STOK PACUL'!C92,'BR DTG PACUL'!E:E) -> 0
A93: 11394-KWB-920 | B93: NOSTOK | C93: 11394-KWB-920 | D93: PERPAK KOPLING H.BLADE/REVO ABSOLUT | E93: 0 | H93: =E93+SUMIF('BR DTG PACUL'!C:C,'STOK PACUL'!C93,'BR DTG PACUL'!E:E) -> 0
A94: 11395-K56-V50 | B94: NOSTOK | C94: 11395-K56-V50 | D94: PERPAK MAGNET H.CB150R ORI | E94: 1 | H94: =E94+SUMIF('BR DTG PACUL'!C:C,'STOK PACUL'!C94,'BR DTG PACUL'!E:E) -> 1
A95: 11395-KGH-901 | B95: NOSTOK | C95: 11395-KGH-901 | D95: PERPAK MAGNET H.CB150R | E95: 0 | H95: =E95+SUMIF('BR DTG PACUL'!C:C,'STOK PACUL'!C95,'BR DTG PACUL'!E:E) -> 0
A96: 11395-KPH-900 | B96: NOSTOK | C96: 11395-KPH-900 | D96: PERPAK MAGNET H.KARISMA/SUPRA X 125 ORI | E96: 0 | H96: =E96+SUMIF('BR DTG PACUL'!C:C,'STOK PACUL'!C96,'BR DTG PACUL'!E:E) -> 0
A97: 11395-KWB-920 | B97: NOSTOK | C97: 11395-KWB-920 | D97: PERPAK MAGNET H.REVO FI ORI | E97: 0 | H97: =E97+SUMIF('BR DTG PACUL'!C:C,'STOK PACUL'!C97,'BR DTG PACUL'!E:E) -> 0
A98: 11482-12K00-000 | B98: NOSTOK | C98: 11482-12K00-000 | D98: PERPAK KOPLING S.SATRIA 150 FI ORI | E98: 0 | H98: =E98+SUMIF('BR DTG PACUL'!C:C,'STOK PACUL'!C98,'BR DTG PACUL'!E:E) -> 0
A99: 11483-46G10-000 | B99: NOSTOK | C99: 11483-46G10-000 | D99: PERPAK MAGNET S.SPIN ORI | E99: 0 | H99: =E99+SUMIF('BR DTG PACUL'!C:C,'STOK PACUL'!C99,'BR DTG PACUL'!E:E) -> 0
A100: 11-6002-2RS1/C3H | B100: NOSTOK | C100: 11-6002-2RS1/C3H | D100: BEARING BALL IMI | E100: 0 | H100: =E100+SUMIF('BR DTG PACUL'!C:C,'STOK PACUL'!C100,'BR DTG PACUL'!E:E) -> 0
A101: 120/70-17 58S | B101: NOSTOK | C101: 120/70-17 58S | D101: BAN TUBLES 120/70-17 ZENEOS | E101: 0 | H101: =E101+SUMIF('BR DTG PACUL'!C:C,'STOK PACUL'!C101,'BR DTG PACUL'!E:E) -> 0
A102: 12100-K03-H10 | B102: NOSTOK | C102: 12100-K03-H10 | D102: BLOK SEHER REVO FI AHM | E102: 0 | H102: =E102+SUMIF('BR DTG PACUL'!C:C,'STOK PACUL'!C102,'BR DTG PACUL'!E:E) -> 0
... A111: 12206-K97-N00 | B111: NOSTOK | C111: 12206-K97-N00 | D111: SELANG RADIATOR 4 ARAH H.VARIO 125 ESP/150/PCX ORI | E111: 0 | H111: =E111+SUMIF('BR DTG PACUL'!C:C,'STOK PACUL'!C111,'BR DTG PACUL'!E:E) -> 0
A112: 12209-GB4-681 | B112: NOSTOK | C112: 12209-GB4-681 | D112: SEAL KLEP H.SET | E112: 0 | F112: 12209-GB4-682 | H112: =E112+SUMIF('BR DTG PACUL'!C:C,'STOK PACUL'!C112,'BR DTG PACUL'!E:E) -> 0
A113: 12209-GB4-682 | B113: MESIN | C113: 12209-GB4-682 | D113: SEAL KLEP H.ORI | E113: 4 | F113: 12209-GB4-682 | H113: =E113+SUMIF('BR DTG PACUL'!C:C,'STOK PACUL'!C113,'BR DTG PACUL'!E:E) -> 4
...

Sheet STOK PESALAKAN
A1: NoItemCOPY | B1: RakBarang | C1: NoItem | D1: NamaItem | E1: Quantity | F1: NOTE | G1: STS | H1: SO+BR DTG | I1: CATATAN
A2: - | B2: NOSTOK | C2: - | D2: - | E2: 0 | H2: =E2+SUMIF('BR DTG ADW'!C:C,C2,'BR DTG ADW'!E:E) -> 0 | I2: JANGAN LUPA KOLOM H COPY RUMUS SAMPAI BAWAH
A3: -- | B3: NOSTOK | C3: -- | D3: - | E3: 0 | H3: =E3+SUMIF('BR DTG ADW'!C:C,C3,'BR DTG ADW'!E:E) -> 0
A4: 011-K44-NPP | B4: NOSTOK | C4: 011-K44-NPP | D4: PISTON KIT H.BEAT FI ESP/POP (1.00) IMI | E4: 0 | H4: =E4+SUMIF('BR DTG ADW'!C:C,C4,'BR DTG ADW'!E:E) -> 0
A5: 011-KPH-950-025 | B5: NOSTOK | C5: 011-KPH-950-025 | D5: RING PISTON H.KARISMA IMI | E5: 0 | H5: =E5+SUMIF('BR DTG ADW'!C:C,C5,'BR DTG ADW'!E:E) -> 0
A6: 01-C21-300-40AA | B6: NOSTOK | C6: 01-C21-300-40AA | D6: BATOK DEPAN SMASH 125 WIN | E6: 0 | H6: =E6+SUMIF('BR DTG ADW'!C:C,C6,'BR DTG ADW'!E:E) -> 0
A7: 01-C21-307-40AA | B7: NOSTOK | C7: 01-C21-307-40AA | D7: SLEBOR DEPAN SMASH 125 WIN | E7: 0 | H7: =E7+SUMIF('BR DTG ADW'!C:C,C7,'BR DTG ADW'!E:E) -> 0
A8: 01-D17-706-99AA | B8: KELISTRIKAN. STATER/ENGKOL | C8: 01-D17-706-99AA | D8: SWITCH REM Y.JUPITER Z IMI | E8: 2 | H8: =E8+SUMIF('BR DTG ADW'!C:C,C8,'BR DTG ADW'!E:E) -> 2
A9: 01-D24-001-00AA | B9: NOSTOK | C9: 01-D24-001-00AA | D9: KACA LAMPU DEPAN MIO | E9: 0 | H9: =E9+SUMIF('BR DTG ADW'!C:C,C9,'BR DTG ADW'!E:E) -> 0
A10: 06141-GN5-505 | B10: NOSTOK | C10: 06141-GN5-505 | D10: RANTE KETENG SUPRA X | E10: 0 | H10: =E10+SUMIF('BR DTG ADW'!C:C,C10,'BR DTG ADW'!E:E) -> 0
A11: 06141-KRS-505 | B11: NOSTOK | C11: 06141-KRS-505 | D11: KETENG SET SUPRAFIT NEW | E11: 0 | H11: =E11+SUMIF('BR DTG ADW'!C:C,C11,'BR DTG ADW'!E:E) -> 0
A12: 06141-KWB-505 | B12: NOSTOK | C12: 06141-KWB-505 | D12: RANTE KETENG SET REVO 110 ABSOLUTE | E12: 0 | H12: =E12+SUMIF('BR DTG ADW'!C:C,C12,'BR DTG ADW'!E:E) -> 0
A13: 06381-KEV-880 | B13: NOSTOK | C13: 06381-KEV-880 | D13: STANG SEHER SUPRA X | E13: 0 | H13: =E13+SUMIF('BR DTG ADW'!C:C,C13,'BR DTG ADW'!E:E) -> 0
A14: 06381-KPH-900 | B14: NOSTOK | C14: 06381-KPH-900 | D14: ROD KIT CONNECTING KARISMA | E14: 0 | H14: =E14+SUMIF('BR DTG ADW'!C:C,C14,'BR DTG ADW'!E:E) -> 0
... A80: 11103-K0J-N00 | B80: NOSTOK | C80: 11103-K0J-N00 | D80: KARET MONTING H.GENIO/SCOOPY NEW/VARIO/ADV/PCX 160 ORI | E80: 0 | H80: =E80+SUMIF('BR DTG ADW'!C:C,C80,'BR DTG ADW'!E:E) -> 0
A81: 11103-KVB-901 | B81: NOSTOK | C81: 11103-KVB-901 | D81: KARET MONTING H.VARIO ORI | E81: 0 | F81: 11103-KVB-930 | H81: =E81+SUMIF('BR DTG ADW'!C:C,C81,'BR DTG ADW'!E:E) -> 0
A82: 11103-KVB-930 | B82: KARET & SELANG | C82: 11103-KVB-930 | D82: KARET MONTING H.VARIO ORI | E82: 2 | F82: 11103-KVB-930 | H82: =E82+SUMIF('BR DTG ADW'!C:C,C82,'BR DTG ADW'!E:E) -> 2
A83: 11108-KVB-900 | B83: NOSTOK | C83: 11108-KVB-900 | D83: PLAT KANCINGAN AS PULLY BEAT/VARIO | E83: 0 | H83: =E83+SUMIF('BR DTG ADW'!C:C,C83,'BR DTG ADW'!E:E) -> 0
A84: 1111-160 | B84: NOSTOK | C84: 1111-160 | D84: SUP RUJI 250-1 H.AHM | E84: 0 | H84: =E84+SUMIF('BR DTG ADW'!C:C,C84,'BR DTG ADW'!E:E) -> 0
A85: 1111-183 | B85: NOSTOK | C85: 1111-183 | D85: SUP/RUJI DEPAN H.SUPRA X 125 ORI | E85: 0 | H85: =E85+SUMIF('BR DTG ADW'!C:C,C85,'BR DTG ADW'!E:E) -> 0
A86: 11203-KVB-901 | B86: NOSTOK | C86: 11203-KVB-901 | D86: BOS SHOCK BELAKANG BAWAH H.BEAT/SCOOPY/VARIO FI ORI | E86: 0 | H86: =E86+SUMIF('BR DTG ADW'!C:C,C86,'BR DTG ADW'!E:E) -> 0
A87: 11210B09G10N000 | B87: NOSTOK | C87: 11210B09G10N000 | D87: BLOK + PISTON S.SMASH ORI | E87: 0 | H87: =E87+SUMIF('BR DTG ADW'!C:C,C87,'BR DTG ADW'!E:E) -> 0
A88: 11361-K44-V00 | B88: NOSTOK | C88: 11361-K44-V00 | D88: TUTUP POMPA OLI BEAT/SCOOPY/ESP | E88: 0 | H88: =E88+SUMIF('BR DTG ADW'!C:C,C88,'BR DTG ADW'!E:E) -> 0
A89: 11363-KWN-900 | B89: KARET & SELANG | C89: 11363-KWN-900 | D89: ORING MAGHNET H.VARIO 125 ORI | E89: 1 | H89: =E89+SUMIF('BR DTG ADW'!C:C,C89,'BR DTG ADW'!E:E) -> 1
A90: 11393-KGH-901 | B90: NOSTOK | C90: 11393-KGH-901 | D90: PERPAK KOPLING H.CB150R ORI | E90: 0 | H90: =E90+SUMIF('BR DTG ADW'!C:C,C90,'BR DTG ADW'!E:E) -> 0
A91: 11394-K56-V50 | B91: NOSTOK | C91: 11394-K56-V50 | D91: PERPAK KOPLING H.CB150R ORI | E91: 0 | H91: =E91+SUMIF('BR DTG ADW'!C:C,C91,'BR DTG ADW'!E:E) -> 0
A92: 11394-KYZ-900 | B92: NOSTOK | C92: 11394-KYZ-900 | D92: PERPAK KOPLING H.SUPRA X 125 FI/HELM IN ORI | E92: 0 | H92: =E92+SUMIF('BR DTG ADW'!C:C,C92,'BR DTG ADW'!E:E) -> 0
A93: 11395-KGH-901 | B93: NOSTOK | C93: 11395-KGH-901 | D93: PERPAK MAGNET H.CB150R ORI | E93: 0 | H93: =E93+SUMIF('BR DTG ADW'!C:C,C93,'BR DTG ADW'!E:E) -> 0
A94: 11395-KPH-900 | B94: NOSTOK | C94: 11395-KPH-900 | D94: PERPAK MAGNET H.KARISMA/SUPRA X 125 ORI | E94: 1 | H94: =E94+SUMIF('BR DTG ADW'!C:C,C94,'BR DTG ADW'!E:E) -> 1
... A110: 12206-KZR-600 | B110: NOSTOK | C110: 12206-KZR-600 | D110: SELANG RADIATOR 4 ARAH H.VARIO 125 LED ORI | E110: 0 | H110: =E110+SUMIF('BR DTG ADW'!C:C,C110,'BR DTG ADW'!E:E) -> 0
A111: 12209-GB4-681 | B111: NOSTOK | C111: 12209-GB4-681 | D111: SEAL KLEP H.SUPRA X 125 ORI | E111: 0 | F111: 12209-GB4-682 | H111: =E111+SUMIF('BR DTG ADW'!C:C,C111,'BR DTG ADW'!E:E) -> 0
A112: 12209-GB4-682 | B112: NOSTOK | C112: 12209-GB4-682 | D112: SEAL KLEP H.SUPRA X 125 ORI | E112: 4 | F112: 12209-GB4-682 | H112: =E112+SUMIF('BR DTG ADW'!C:C,C112,'BR DTG ADW'!E:E) -> 4
A113: 12251-GGC-901 | B113: NOSTOK | C113: 12251-GGC-901 | D113: PERPAK HEAD H.BEAT FI ESP ORI | E113: 1 | H113: =E113+SUMIF('BR DTG ADW'!C:C,C113,'BR DTG ADW'!E:E) -> 1
A114: 12251-K0J-N01 | B114: NOSTOK | C114: 12251-K0J-N01 | D114: PERPAK HEAD H.GENIO/BEAT/SCOOPY LED ORI | E114: 0 | H114: =E114+SUMIF('BR DTG ADW'!C:C,C114,'BR DTG ADW'!E:E) -> 0
A115: 12251-K12-901 | B115: NOSTOK | C115: 12251-K12-901 | D115: PERPAK HEAD H.VARIO 125 ORI | E115: 1 | F115: 12251-K12-901 | H115: =E115+SUMIF('BR DTG ADW'!C:C,C115,'BR DTG ADW'!E:E) -> 1
A116: 12251-K15-900 | B116: NOSTOK | C116: 12251-K15-900 | D116: PERPAK HEAD H.CB150R ORI | E116: 0 | H116: =E116+SUMIF('BR DTG ADW'!C:C,C116,'BR DTG ADW'!E:E) -> 0
A117: 12251-K56-N02 | B117: NOSTOK | C117: 12251-K56-N02 | D117: PERPAK HEAD H.CB150R/CBR ORI | E117: 0 | H117: =E117+SUMIF('BR DTG ADW'!C:C,C117,'BR DTG ADW'!E:E) -> 0
A118: 12251-K78-V01 | B118: NOSTOK | C118: 12251-K78-V01 | D118: PERPAK HEAD H.VARIO 150 NEWORI | E118: 0 | H118: =E118+SUMIF('BR DTG ADW'!C:C,C118,'BR DTG ADW'!E:E) -> 0
A119: 12251-K97-T01 | B119: NOSTOK | C119: 12251-K97-T01 | D119: PERPAK HEAD H.PCX 150 ORI | E119: 0 | F119: 12251-K97-T01 | H119: =E119+SUMIF('BR DTG ADW'!C:C,C119,'BR DTG ADW'!E:E) -> 0
A120: 12251-KRM-B41 | B120: NOSTOK | C120: 12251-KRM-B41 | D120: PERPAK HEAD H.MEGAPRO ORI | E120: 0 | H120: =E120+SUMIF('BR DTG ADW'!C:C,C120,'BR DTG ADW'!E:E) -> 0
...

Sheet STOK CIKDITIRO
A1: NoItemCOPY | B1: RakBarang | C1: NoItem | D1: NamaItem | E1: Quantity | F1: NOTE | G1: STS | H1: SO+BR DTG | I1: CATATAN
A2: - | B2: NOSTOK | C2: - | D2: - | E2: 0 | H2: =E2+SUMIF('BR DTG CIKDITIRO'!C:C,C2,'BR DTG CIKDITIRO'!E:E) -> 0 | I2: JANGAN LUPA KOLOM H COPY RUMUS SAMPAI BAWAH
A3: -- | B3: NOSTOK | C3: -- | D3: - | E3: 0 | H3: =E3+SUMIF('BR DTG CIKDITIRO'!C:C,C3,'BR DTG CIKDITIRO'!E:E) -> 0
A4: 011-GN5-NPP PK C | B4: NOSTOK | C4: 011-GN5-NPP PK C | D4: PISTON KIT H. SUPRA GRAND NPP (STD) IMI | E4: 0 | H4: =E4+SUMIF('BR DTG CIKDITIRO'!C:C,C4,'BR DTG CIKDITIRO'!E:E) -> 0
A5: 011-K44-NPP | B5: NOSTOK | C5: 011-K44-NPP | D5: PISTON KIT H.BEAT FI ESP/POP (1.00) ORI | E5: 0 | H5: =E5+SUMIF('BR DTG CIKDITIRO'!C:C,C5,'BR DTG CIKDITIRO'!E:E) -> 0
A6: 011-K59-0705 | B6: NOSTOK | C6: 011-K59-0705 | D6: STANG SEHER VARIO 150 IMI NPP | E6: 0 | H6: =E6+SUMIF('BR DTG CIKDITIRO'!C:C,C6,'BR DTG CIKDITIRO'!E:E) -> 0
A7: 011-K97-0705 NPP | B7: NOSTOK | C7: 011-K97-0705 NPP | D7: STANG SEHER H. PCX 150 ORI | E7: 0 | H7: =E7+SUMIF('BR DTG CIKDITIRO'!C:C,C7,'BR DTG CIKDITIRO'!E:E) -> 0
A8: 011-KPH-950-025 | B8: NOSTOK | C8: 011-KPH-950-025 | D8: RING PISTON H.KARISMA IMI | E8: 0 | H8: =E8+SUMIF('BR DTG CIKDITIRO'!C:C,C8,'BR DTG CIKDITIRO'!E:E) -> 0
A9: 011-KPH-NPP PK | B9: NOSTOK | C9: 011-KPH-NPP PK | D9: PISTON KIT H.KARISMA NPP (1.25) | E9: 0 | H9: =E9+SUMIF('BR DTG CIKDITIRO'!C:C,C9,'BR DTG CIKDITIRO'!E:E) -> 0
A10: 011-KPP-0705 | B10: NOSTOK | C10: 011-KPP-0705 | D10: STANG SEHER H.CB150R IMI | E10: 0 | H10: =E10+SUMIF('BR DTG CIKDITIRO'!C:C,C10,'BR DTG CIKDITIRO'!E:E) -> 0
A11: 011-KVB NPP PK | B11: NOSTOK | C11: 011-KVB NPP PK | D11: PISTON KIT H.VARIO CARBU NPP (1.25) | E11: 0 | H11: =E11+SUMIF('BR DTG CIKDITIRO'!C:C,C11,'BR DTG CIKDITIRO'!E:E) -> 0
A12: 01-C21-300-40AA | B12: NOSTOK | C12: 01-C21-300-40AA | D12: BATOK DEPAN SMASH 125 WIN | E12: 0 | H12: =E12+SUMIF('BR DTG CIKDITIRO'!C:C,C12,'BR DTG CIKDITIRO'!E:E) -> 0
A13: 01-C21-307-40AA | B13: NOSTOK | C13: 01-C21-307-40AA | D13: SLEBOR DEPAN SMASH 125 WIN | E13: 0 | H13: =E13+SUMIF('BR DTG CIKDITIRO'!C:C,C13,'BR DTG CIKDITIRO'!E:E) -> 0
A14: 01-D17-706-99AA | B14: NOSTOK | C14: 01-D17-706-99AA | D14: SWITCH REM Y.JUPITER Z IMI | E14: 0 | H14: =E14+SUMIF('BR DTG CIKDITIRO'!C:C,C14,'BR DTG CIKDITIRO'!E:E) -> 0
... A91: 1110-159NSNB | B91: NOSTOK | C91: 1110-159NSNB | D91: SUP/RUJI BELAKANG H.SUPRA X 125 ORI | E91: 0 | H91: =E91+SUMIF('BR DTG CIKDITIRO'!C:C,C91,'BR DTG CIKDITIRO'!E:E) -> 0
A92: 11103-KVB-901 | B92: NOSTOK | C92: 11103-KVB-901 | D92: KARET MONTING H.VARIO ORI | E92: 0 | F92: 11103-KVB-930 | H92: =E92+SUMIF('BR DTG CIKDITIRO'!C:C,C92,'BR DTG CIKDITIRO'!E:E) -> 0
A93: 11103-KVB-930 | B93: KARET & SELANG | C93: 11103-KVB-930 | D93: KARET MONTING H.VARIO ORI | E93: 2 | F93: 11103-KVB-930 | H93: =E93+SUMIF('BR DTG CIKDITIRO'!C:C,C93,'BR DTG CIKDITIRO'!E:E) -> 2
A94: 11108-KVB-900 | B94: NOSTOK | C94: 11108-KVB-900 | D94: PLAT KANCINGAN AS PULLY BEAT/VARIO | E94: 0 | H94: =E94+SUMIF('BR DTG CIKDITIRO'!C:C,C94,'BR DTG CIKDITIRO'!E:E) -> 0
A95: 1111-160 | B95: NOSTOK | C95: 1111-160 | D95: SUP RUJI 250-1 H.AHM | E95: 0 | H95: =E95+SUMIF('BR DTG CIKDITIRO'!C:C,C95,'BR DTG CIKDITIRO'!E:E) -> 0
A96: 1111-183 | B96: NOSTOK | C96: 1111-183 | D96: SUP/RUJI DEPAN H.SUPRA X 125 ORI | E96: 0 | H96: =E96+SUMIF('BR DTG CIKDITIRO'!C:C,C96,'BR DTG CIKDITIRO'!E:E) -> 0
A97: 11203-KVB-901 | B97: NOSTOK | C97: 11203-KVB-901 | D97: BOS SHOCK BELAKANG BAWAH H.BEAT/SCOOPY/VARIO FI ORI | E97: 0 | H97: =E97+SUMIF('BR DTG CIKDITIRO'!C:C,C97,'BR DTG CIKDITIRO'!E:E) -> 0
A98: 11210B09G10N000 | B98: NOSTOK | C98: 11210B09G10N000 | D98: BLOK + PISTON S.SMASH ORI | E98: 0 | H98: =E98+SUMIF('BR DTG CIKDITIRO'!C:C,C98,'BR DTG CIKDITIRO'!E:E) -> 0
A99: 11345-K56-N50 | B99: NOSTOK | C99: 11345-K56-N50 | D99: PERPAK MAGNET H.CB150R ORI | E99: 0 | H99: =E99+SUMIF('BR DTG CIKDITIRO'!C:C,C99,'BR DTG CIKDITIRO'!E:E) -> 0
A100: 11361-K44-V00 | B100: NOSTOK | C100: 11361-K44-V00 | D100: TUTUP POMPA OLI BEAT/SCOOPY/ESP | E100: 0 | H100: =E100+SUMIF('BR DTG CIKDITIRO'!C:C,C100,'BR DTG CIKDITIRO'!E:E) -> 0
A101: 11363-KWN-900 | B101: KARET & SELANG | C101: 11363-KWN-900 | D101: ORING MAGHNET H.VARIO 125 ORI | E101: 1 | H101: =E101+SUMIF('BR DTG CIKDITIRO'!C:C,C101,'BR DTG CIKDITIRO'!E:E) -> 1
A102: 11393-KGH-901 | B102: NOSTOK | C102: 11393-KGH-901 | D102: PERPAK KOPLING H.CB150R ORI | E102: 1 | H102: =E102+SUMIF('BR DTG CIKDITIRO'!C:C,C102,'BR DTG CIKDITIRO'!E:E) -> 1
A103: 11394-K56-V50 | B103: NOSTOK | C103: 11394-K56-V50 | D103: PERPAK KOPLING H. CBR150R ORI | E103: 0 | H103: =E103+SUMIF('BR DTG CIKDITIRO'!C:C,C103,'BR DTG CIKDITIRO'!E:E) -> 0
A104: 11395-KPH-900 | B104: NOSTOK | C104: 11395-KPH-900 | D104: PERPAK MAGNET H.KARISMA/SUPRA X 125 ORI | E104: 0 | H104: =E104+SUMIF('BR DTG CIKDITIRO'!C:C,C104,'BR DTG CIKDITIRO'!E:E) -> 0
A105: 11-6002-2RS1/C3H | B105: NOSTOK | C105: 11-6002-2RS1/C3H | D105: BEARING BALL IMI | E105: 0 | H105: =E105+SUMIF('BR DTG CIKDITIRO'!C:C,C105,'BR DTG CIKDITIRO'!E:E) -> 0
... A114: 12204-KVY-901 | B114: NOSTOK | C114: 12204-KVY-901 | D114: BOS KLEP BEAT/ SPACY | E114: 0 | H114: =E114+SUMIF('BR DTG CIKDITIRO'!C:C,C114,'BR DTG CIKDITIRO'!E:E) -> 0
A115: 12209-GB4-681 | B115: NOSTOK | C115: 12209-GB4-681 | D115: SEAL KLEP H.BEAT FI | E115: 0 | F115: 12209-GB4-682 | H115: =E115+SUMIF('BR DTG CIKDITIRO'!C:C,C115,'BR DTG CIKDITIRO'!E:E) -> 0
A116: 12209-GB4-682 | B116: MESIN | C116: 12209-GB4-682 | D116: SEAL KLEP H.SUPRA X 125 ORI | E116: 2 | F116: 12209-GB4-682 | H116: =E116+SUMIF('BR DTG CIKDITIRO'!C:C,C116,'BR DTG CIKDITIRO'!E:E) -> 2
A117: 12245-GB4-305 | B117: NOSTOK | C117: 12245-GB4-305 | D117: BOS KLEP H.SUPRA | E117: 0 | H117: =E117+SUMIF('BR DTG CIKDITIRO'!C:C,C117,'BR DTG CIKDITIRO'!E:E) -> 0
A118: 12251-GGC-901 | B118: NOSTOK | C118: 12251-GGC-901 | D118: PERPAK HEAD H.BEAT FI ORI | E118: 3 | H118: =E118+SUMIF('BR DTG CIKDITIRO'!C:C,C118,'BR DTG CIKDITIRO'!E:E) -> 3
A119: 12251-K12-901 | B119: NOSTOK | C119: 12251-K12-901 | D119: PERPAK CHTP-SILINDER HEAD | E119: 1 | F119: 12251-K12-901 | H119: =E119+SUMIF('BR DTG CIKDITIRO'!C:C,C119,'BR DTG CIKDITIRO'!E:E) -> 1
A120: 12251-K15-900 | B120: NOSTOK | C120: 12251-K15-900 | D120: PERPAK HEAD H.CB150R 13 / CBR150R 11-14 ORI | E120: 0 | H120: =E120+SUMIF('BR DTG CIKDITIRO'!C:C,C120,'BR DTG CIKDITIRO'!E:E) -> 0
A121: 12251-K1Z-J11 | B121: NOSTOK | C121: 12251-K1Z-J11 | D121: PERPAK HEAD H. PCX 160/VARIO 160/STYLO ORI | E121: 0 | H121: =E121+SUMIF('BR DTG CIKDITIRO'!C:C,C121,'BR DTG CIKDITIRO'!E:E) -> 0
A122: 12251-K56-N02 | B122: NOSTOK | C122: 12251-K56-N02 | D122: PERPAK HEAD H.CB150R/CBR ORI | E122: 0 | H122: =E122+SUMIF('BR DTG CIKDITIRO'!C:C,C122,'BR DTG CIKDITIRO'!E:E) -> 0
A123: 12251-K78-00 | B123: NOSTOK | C123: 12251-K78-00 | D123: PERPAK HEAD H.VARIO 150 | E123: 0 | H123: =E123+SUMIF('BR DTG CIKDITIRO'!C:C,C123,'BR DTG CIKDITIRO'!E:E) -> 0
A124: 12251-K97-T01 | B124: NOSTOK | C124: 12251-K97-T01 | D124: PERPAK HEAD H.VARIO 150 ORI | E124: 1 | F124: 12251-K97-T01 | H124: =E124+SUMIF('BR DTG CIKDITIRO'!C:C,C124,'BR DTG CIKDITIRO'!E:E) -> 1
...

Sheet STOK TRAYEMAN
A1: NoItemCOPY | B1: RakBarang | C1: NoItem | D1: NamaItem | E1: Quantity | F1: NOTE | G1: STS | H1: SO+BR DTG | I1: CATATAN
A2: - | B2: NOSTOK | C2: - | D2: - | E2: 0 | H2: =E2+SUMIF('BR DTG TRAYEMAN'!C:C,C2,'BR DTG TRAYEMAN'!E:E) -> 0 | I2: JANGAN LUPA KOLOM H COPY RUMUS SAMPAI BAWAH
A3: -- | B3: NOSTOK | C3: -- | D3: - | E3: 0 | H3: =E3+SUMIF('BR DTG TRAYEMAN'!C:C,C3,'BR DTG TRAYEMAN'!E:E) -> 0
A4: 011-GN5-NPP PK C | B4: NOSTOK | C4: 011-GN5-NPP PK C | D4: PISTON KIT H. SUPRA GRAND NPP (STD) IMI | E4: 0 | H4: =E4+SUMIF('BR DTG TRAYEMAN'!C:C,C4,'BR DTG TRAYEMAN'!E:E) -> 0
A5: 011-K44-NPP | B5: NOSTOK | C5: 011-K44-NPP | D5: PISTON KIT H.BEAT FI ESP/POP (1.00) ORI | E5: 0 | H5: =E5+SUMIF('BR DTG TRAYEMAN'!C:C,C5,'BR DTG TRAYEMAN'!E:E) -> 0
A6: 011-K59-0705 | B6: NOSTOK | C6: 011-K59-0705 | D6: STANG SEHER VARIO 150 IMI NPP | E6: 0 | H6: =E6+SUMIF('BR DTG TRAYEMAN'!C:C,C6,'BR DTG TRAYEMAN'!E:E) -> 0
A7: 011-K97-0705 NPP | B7: NOSTOK | C7: 011-K97-0705 NPP | D7: STANG SEHER H. PCX 150 ORI | E7: 0 | H7: =E7+SUMIF('BR DTG TRAYEMAN'!C:C,C7,'BR DTG TRAYEMAN'!E:E) -> 0
A8: 011-KPH-950-025 | B8: NOSTOK | C8: 011-KPH-950-025 | D8: RING PISTON H.KARISMA IMI | E8: 0 | H8: =E8+SUMIF('BR DTG TRAYEMAN'!C:C,C8,'BR DTG TRAYEMAN'!E:E) -> 0
A9: 011-KPH-NPP PK | B9: NOSTOK | C9: 011-KPH-NPP PK | D9: PISTON KIT H.KARISMA NPP (1.25) | E9: 0 | H9: =E9+SUMIF('BR DTG TRAYEMAN'!C:C,C9,'BR DTG TRAYEMAN'!E:E) -> 0
A10: 011-KPP-0705 | B10: NOSTOK | C10: 011-KPP-0705 | D10: STANG SEHER H.CB150R IMI | E10: 0 | H10: =E10+SUMIF('BR DTG TRAYEMAN'!C:C,C10,'BR DTG TRAYEMAN'!E:E) -> 0
A11: 011-KVB NPP PK | B11: NOSTOK | C11: 011-KVB NPP PK | D11: PISTON KIT H.VARIO CARBU NPP (1.25) | E11: 0 | H11: =E11+SUMIF('BR DTG TRAYEMAN'!C:C,C11,'BR DTG TRAYEMAN'!E:E) -> 0
A12: 01-C21-300-40AA | B12: NOSTOK | C12: 01-C21-300-40AA | D12: BATOK DEPAN SMASH 125 WIN | E12: 0 | H12: =E12+SUMIF('BR DTG TRAYEMAN'!C:C,C12,'BR DTG TRAYEMAN'!E:E) -> 0
A13: 01-C21-307-40AA | B13: NOSTOK | C13: 01-C21-307-40AA | D13: SLEBOR DEPAN SMASH 125 WIN | E13: 0 | H13: =E13+SUMIF('BR DTG TRAYEMAN'!C:C,C13,'BR DTG TRAYEMAN'!E:E) -> 0
A14: 01-D17-706-99AA | B14: NOSTOK | C14: 01-D17-706-99AA | D14: SWITCH REM Y.JUPITER Z IMI | E14: 0 | H14: =E14+SUMIF('BR DTG TRAYEMAN'!C:C,C14,'BR DTG TRAYEMAN'!E:E) -> 0
... A91: 1110-159NSNB | B91: NOSTOK | C91: 1110-159NSNB | D91: SUP/RUJI BELAKANG H.SUPRA X 125 ORI | E91: 0 | H91: =E91+SUMIF('BR DTG TRAYEMAN'!C:C,C91,'BR DTG TRAYEMAN'!E:E) -> 0
A92: 11103-KVB-901 | B92: NOSTOK | C92: 11103-KVB-901 | D92: KARET MONTING H.VARIO ORI | E92: 0 | F92: 11103-KVB-930 | H92: =E92+SUMIF('BR DTG TRAYEMAN'!C:C,C92,'BR DTG TRAYEMAN'!E:E) -> 0
A93: 11103-KVB-930 | B93: KARET & SELANG | C93: 11103-KVB-930 | D93: KARET MONTING H.VARIO ORI | E93: 0 | F93: 11103-KVB-930 | H93: =E93+SUMIF('BR DTG TRAYEMAN'!C:C,C93,'BR DTG TRAYEMAN'!E:E) -> 0
A94: 11108-KVB-900 | B94: NOSTOK | C94: 11108-KVB-900 | D94: PLAT KANCINGAN AS PULLY BEAT/VARIO | E94: 0 | H94: =E94+SUMIF('BR DTG TRAYEMAN'!C:C,C94,'BR DTG TRAYEMAN'!E:E) -> 0
A95: 1111-160 | B95: NOSTOK | C95: 1111-160 | D95: SUP RUJI 250-1 H.AHM | E95: 0 | H95: =E95+SUMIF('BR DTG TRAYEMAN'!C:C,C95,'BR DTG TRAYEMAN'!E:E) -> 0
A96: 1111-183 | B96: NOSTOK | C96: 1111-183 | D96: SUP/RUJI DEPAN H.SUPRA X 125 ORI | E96: 0 | H96: =E96+SUMIF('BR DTG TRAYEMAN'!C:C,C96,'BR DTG TRAYEMAN'!E:E) -> 0
A97: 11203-KVB-901 | B97: NOSTOK | C97: 11203-KVB-901 | D97: BOS SHOCK BELAKANG BAWAH H.BEAT/SCOOPY/VARIO FI ORI | E97: 0 | H97: =E97+SUMIF('BR DTG TRAYEMAN'!C:C,C97,'BR DTG TRAYEMAN'!E:E) -> 0
A98: 11210B09G10N000 | B98: NOSTOK | C98: 11210B09G10N000 | D98: BLOK + PISTON S.SMASH ORI | E98: 0 | H98: =E98+SUMIF('BR DTG TRAYEMAN'!C:C,C98,'BR DTG TRAYEMAN'!E:E) -> 0
A99: 11345-K56-N50 | B99: NOSTOK | C99: 11345-K56-N50 | D99: PERPAK MAGNET H.CB150R ORI | E99: 0 | H99: =E99+SUMIF('BR DTG TRAYEMAN'!C:C,C99,'BR DTG TRAYEMAN'!E:E) -> 0
A100: 11361-K44-V00 | B100: NOSTOK | C100: 11361-K44-V00 | D100: TUTUP POMPA OLI BEAT/SCOOPY/ESP | E100: 0 | H100: =E100+SUMIF('BR DTG TRAYEMAN'!C:C,C100,'BR DTG TRAYEMAN'!E:E) -> 0
A101: 11363-KWN-900 | B101: KARET & SELANG | C101: 11363-KWN-900 | D101: ORING MAGHNET H.VARIO 125 ORI | E101: 0 | H101: =E101+SUMIF('BR DTG TRAYEMAN'!C:C,C101,'BR DTG TRAYEMAN'!E:E) -> 0
A102: 11393-KGH-901 | B102: NOSTOK | C102: 11393-KGH-901 | D102: PERPAK KOPLING H.CB150R ORI | E102: 0 | H102: =E102+SUMIF('BR DTG TRAYEMAN'!C:C,C102,'BR DTG TRAYEMAN'!E:E) -> 0
A103: 11394-K56-V50 | B103: NOSTOK | C103: 11394-K56-V50 | D103: PERPAK KOPLING H. CBR150R ORI | E103: 0 | H103: =E103+SUMIF('BR DTG TRAYEMAN'!C:C,C103,'BR DTG TRAYEMAN'!E:E) -> 0
A104: 11395-KPH-900 | B104: NOSTOK | C104: 11395-KPH-900 | D104: PERPAK MAGNET H.KARISMA/SUPRA X 125 ORI | E104: 0 | H104: =E104+SUMIF('BR DTG TRAYEMAN'!C:C,C104,'BR DTG TRAYEMAN'!E:E) -> 0
A105: 11-6002-2RS1/C3H | B105: NOSTOK | C105: 11-6002-2RS1/C3H | D105: BEARING BALL IMI | E105: 0 | H105: =E105+SUMIF('BR DTG TRAYEMAN'!C:C,C105,'BR DTG TRAYEMAN'!E:E) -> 0
... A114: 12204-KVY-901 | B114: NOSTOK | C114: 12204-KVY-901 | D114: BOS KLEP BEAT/ SPACY | E114: 0 | H114: =E114+SUMIF('BR DTG TRAYEMAN'!C:C,C114,'BR DTG TRAYEMAN'!E:E) -> 0
A115: 12209-GB4-681 | B115: NOSTOK | C115: 12209-GB4-681 | D115: SEAL KLEP H.BEAT FI | E115: 0 | F115: 12209-GB4-682 | H115: =E115+SUMIF('BR DTG TRAYEMAN'!C:C,C115,'BR DTG TRAYEMAN'!E:E) -> 0
A116: 12209-GB4-682 | B116: MESIN | C116: 12209-GB4-682 | D116: SEAL KLEP H.SUPRA X 125 ORI | E116: 0 | F116: 12209-GB4-682 | H116: =E116+SUMIF('BR DTG TRAYEMAN'!C:C,C116,'BR DTG TRAYEMAN'!E:E) -> 0
A117: 12245-GB4-305 | B117: NOSTOK | C117: 12245-GB4-305 | D117: BOS KLEP H.SUPRA | E117: 0 | H117: =E117+SUMIF('BR DTG TRAYEMAN'!C:C,C117,'BR DTG TRAYEMAN'!E:E) -> 0
A118: 12251-GGC-901 | B118: NOSTOK | C118: 12251-GGC-901 | D118: PERPAK HEAD H.BEAT FI ORI | E118: 0 | H118: =E118+SUMIF('BR DTG TRAYEMAN'!C:C,C118,'BR DTG TRAYEMAN'!E:E) -> 0
A119: 12251-K12-901 | B119: NOSTOK | C119: 12251-K12-901 | D119: PERPAK CHTP-SILINDER HEAD | E119: 0 | F119: 12251-K12-901 | H119: =E119+SUMIF('BR DTG TRAYEMAN'!C:C,C119,'BR DTG TRAYEMAN'!E:E) -> 0
A120: 12251-K15-900 | B120: NOSTOK | C120: 12251-K15-900 | D120: PERPAK HEAD H.CB150R 13 / CBR150R 11-14 ORI | E120: 0 | H120: =E120+SUMIF('BR DTG TRAYEMAN'!C:C,C120,'BR DTG TRAYEMAN'!E:E) -> 0
A121: 12251-K1Z-J11 | B121: NOSTOK | C121: 12251-K1Z-J11 | D121: PERPAK HEAD H. PCX 160/VARIO 160/STYLO ORI | E121: 0 | H121: =E121+SUMIF('BR DTG TRAYEMAN'!C:C,C121,'BR DTG TRAYEMAN'!E:E) -> 0
A122: 12251-K56-N02 | B122: NOSTOK | C122: 12251-K56-N02 | D122: PERPAK HEAD H.CB150R/CBR ORI | E122: 0 | H122: =E122+SUMIF('BR DTG TRAYEMAN'!C:C,C122,'BR DTG TRAYEMAN'!E:E) -> 0
A123: 12251-K78-00 | B123: NOSTOK | C123: 12251-K78-00 | D123: PERPAK HEAD H.VARIO 150 | E123: 0 | H123: =E123+SUMIF('BR DTG TRAYEMAN'!C:C,C123,'BR DTG TRAYEMAN'!E:E) -> 0
A124: 12251-K97-T01 | B124: NOSTOK | C124: 12251-K97-T01 | D124: PERPAK HEAD H.VARIO 150 ORI | E124: 0 | F124: 12251-K97-T01 | H124: =E124+SUMIF('BR DTG TRAYEMAN'!C:C,C124,'BR DTG TRAYEMAN'!E:E) -> 0
...

Sheet FR_HITUNG_MINMAX
A1: NoItem | B1: NamaItem | C1: RakBarang | D1: Jenis | E1: STATUS | F1: HargaPokok | G1: StokMin | H1: Supplier | I1: Supplier2 | J1: Supplier3 | K1: HJQtyS1 | L1: W1 | M1: W2 | N1: W3 | O1: W4 | P1: W5 | Q1: W6 | R1: W7 | S1: W8 | T1: W9 | U1: W10 | V1: W11 | W1: W12 | X1: MAX_1W | Y1: 2W1 | Z1: 2W2 | AA1: 2W3 | AB1: 2W4 | AC1: 2W5 | AD1: 2W6 | AE1: 2W7 | AF1: 2W8 | AG1: 2W9 | AH1: 2W10 | AI1: 2W11 | AJ1: 2W12 | AK1: MAX_2W | AL1: MIN_STOK | AM1: MAX_STOK | AN1: STS | AO1: Quantity | AP1: BR DTG | AQ1: SO+BR DTG | AR1: STOK | AS1: JUAL 3 HARI | AT1: CEK JML ITEM
A2: 06141-KWB-505 | B2: RANTE KETENG SET REVO 110 ABSOLUTE | C2: NOSTOK | D2: ORISIN | E2: D | F2: 56500 | G2: 1 | H2: GSM | J2: 1 | K2: 1 | L2: 1 | M2: 0 | N2: 0 | O2: 0 | P2: 0 | Q2: 0 | R2: 0 | S2: 0 | T2: 0 | U2: 0 | V2: 0 | W2: 0 | X2: 1 | Y2: 1 | Z2: 0 | AA2: 0 | AB2: 0 | AC2: 0 | AD2: 0 | AE2: 0 | AF2: 0 | AG2: 0 | AH2: 0 | AI2: 0 | AJ2: 1 | AK2: 1 | AL2: 0 | AM2: 0 | AN2: PACUL | AO2: 0 | AP2: =IFERROR(IF(AN2="CIKDITIRO",VLOOKUP(A2,'BR DTG CIKDITIRO'!C:E,3,0),IF(FR_HITUNG_MINMAX!AN2="PESALAKAN",VLOOKUP(FR_HITUNG_MINMAX!A2,'BR DTG ADW'!C:E,3,0),IF(FR_HITUNG_MINMAX!AN2="PACUL",VLOOKUP(FR_HITUNG_MINMAX!A2,'BR DTG PACUL'!C:E,3,0),IF(FR_HITUNG_MINMAX!AN2="TRAYEMAN",VLOOKUP(FR_HITUNG_MINMAX!A2,'BR DTG TRAYEMAN'!C:E,3,0),"?")))),0) -> 0 | AQ2: =IF(AN2="PACUL",VLOOKUP(A2,'STOK PACUL'!C:H,6,0),IF(FR_HITUNG_MINMAX!AN2="PESALAKAN",VLOOKUP(FR_HITUNG_MINMAX!A2,'STOK PESALAKAN'!C:H,6,0),IF(FR_HITUNG_MINMAX!AN2="CIKDITIRO",VLOOKUP(FR_HITUNG_MINMAX!A2,'STOK CIKDITIRO'!C:H,6,0),IF(FR_HITUNG_MINMAX!AN2="TRAYEMAN",VLOOKUP(FR_HITUNG_MINMAX!A2,'STOK TRAYEMAN'!C:H,6,0),"?")))) -> 0 | AR2: =IFERROR(AQ2,AO2+AP2) -> 0 | AS2: =ROUNDUP(AL2/2,0) -> 0 | AT2: =COUNTIF(A:A,A2) -> 1 | AU2: Kolom G (stokmin), kolom J (supplier3) dan kolom K (HJQtyS1) yang kosong diisi angka 1
A3: 06381-KZL-A00 | B3: STANG SEHER H.BEAT FI AHM | C3: NOSTOK | D3: ORISIN | E3: D | F3: 168000 | G3: 1 | H3: GSM | J3: 1 | K3: 1 | L3: 0 | M3: 0 | N3: 0 | O3: 0 | P3: 0 | Q3: 0 | R3: 1 | S3: 0 | T3: 0 | U3: 0 | V3: 0 | W3: 0 | X3: 1 | Y3: 0 | Z3: 0 | AA3: 0 | AB3: 0 | AC3: 0 | AD3: 1 | AE3: 1 | AF3: 0 | AG3: 0 | AH3: 0 | AI3: 0 | AJ3: 0 | AK3: 1 | AL3: 0 | AM3: 0 | AN3: PACUL | AO3: 0 | AP3: =IFERROR(IF(AN3="CIKDITIRO",VLOOKUP(A3,'BR DTG CIKDITIRO'!C:E,3,0),IF(FR_HITUNG_MINMAX!AN3="PESALAKAN",VLOOKUP(FR_HITUNG_MINMAX!A3,'BR DTG ADW'!C:E,3,0),IF(FR_HITUNG_MINMAX!AN3="PACUL",VLOOKUP(FR_HITUNG_MINMAX!A3,'BR DTG PACUL'!C:E,3,0),IF(FR_HITUNG_MINMAX!AN3="TRAYEMAN",VLOOKUP(FR_HITUNG_MINMAX!A3,'BR DTG TRAYEMAN'!C:E,3,0),"?")))),0) -> 0 | AQ3: =IF(AN3="PACUL",VLOOKUP(A3,'STOK PACUL'!C:H,6,0),IF(FR_HITUNG_MINMAX!AN3="PESALAKAN",VLOOKUP(FR_HITUNG_MINMAX!A3,'STOK PESALAKAN'!C:H,6,0),IF(FR_HITUNG_MINMAX!AN3="CIKDITIRO",VLOOKUP(FR_HITUNG_MINMAX!A3,'STOK CIKDITIRO'!C:H,6,0),IF(FR_HITUNG_MINMAX!AN3="TRAYEMAN",VLOOKUP(FR_HITUNG_MINMAX!A3,'STOK TRAYEMAN'!C:H,6,0),"?")))) -> 0 | AR3: =IFERROR(AQ3,AO3+AP3) -> 0 | AS3: =ROUNDUP(AL3/2,0) -> 0 | AT3: =COUNTIF(A:A,A3) -> 1
A4: 06381-KZR-600 | B4: SETANG SEHER H.VARIO 125 ORI | C4: NOSTOK | D4: ORISIN | E4: D | F4: 162500 | G4: 1 | H4: NJM | I4: NSA | J4: 1 | K4: 1 | L4: 0 | M4: 0 | N4: 0 | O4: 1 | P4: 0 | Q4: 0 | R4: 0 | S4: 0 | T4: 0 | U4: 0 | V4: 0 | W4: 0 | X4: 1 | Y4: 0 | Z4: 0 | AA4: 1 | AB4: 1 | AC4: 0 | AD4: 0 | AE4: 0 | AF4: 0 | AG4: 0 | AH4: 0 | AI4: 0 | AJ4: 0 | AK4: 1 | AL4: 0 | AM4: 0 | AN4: PACUL | AO4: 0 | AP4: =IFERROR(IF(AN4="CIKDITIRO",VLOOKUP(A4,'BR DTG CIKDITIRO'!C:E,3,0),IF(FR_HITUNG_MINMAX!AN4="PESALAKAN",VLOOKUP(FR_HITUNG_MINMAX!A4,'BR DTG ADW'!C:E,3,0),IF(FR_HITUNG_MINMAX!AN4="PACUL",VLOOKUP(FR_HITUNG_MINMAX!A4,'BR DTG PACUL'!C:E,3,0),IF(FR_HITUNG_MINMAX!AN4="TRAYEMAN",VLOOKUP(FR_HITUNG_MINMAX!A4,'BR DTG TRAYEMAN'!C:E,3,0),"?")))),0) -> 0 | AQ4: =IF(AN4="PACUL",VLOOKUP(A4,'STOK PACUL'!C:H,6,0),IF(FR_HITUNG_MINMAX!AN4="PESALAKAN",VLOOKUP(FR_HITUNG_MINMAX!A4,'STOK PESALAKAN'!C:H,6,0),IF(FR_HITUNG_MINMAX!AN4="CIKDITIRO",VLOOKUP(FR_HITUNG_MINMAX!A4,'STOK CIKDITIRO'!C:H,6,0),IF(FR_HITUNG_MINMAX!AN4="TRAYEMAN",VLOOKUP(FR_HITUNG_MINMAX!A4,'STOK TRAYEMAN'!C:H,6,0),"?")))) -> 0 | AR4: =IFERROR(AQ4,AO4+AP4) -> 0 | AS4: =ROUNDUP(AL4/2,0) -> 0 | AT4: =COUNTIF(A:A,A4) -> 3 | AU4: =COUNTIF(AT:AT,"1") -> 420
A5: 06401-KPH-881 | B5: GIR SET H.KARISMA/SUPRA X 125 ORI | C5: RODA | D5: ORISIN | E5: D | F5: 185000 | G5: 1 | H5: GSM | I5: NSA | J5: 1 | K5: 1 | L5: 0 | M5: 1 | N5: 0 | O5: 1 | P5: 1 | Q5: 0 | R5: 0 | S5: 0 | T5: 0 | U5: 0 | V5: 0 | W5: 0 | X5: 1 | Y5: 1 | Z5: 1 | AA5: 1 | AB5: 2 | AC5: 1 | AD5: 0 | AE5: 0 | AF5: 0 | AG5: 0 | AH5: 0 | AI5: 0 | AJ5: 0 | AK5: 2 | AL5: 1 | AM5: 2 | AN5: PACUL | AO5: 2 | AP5: =IFERROR(IF(AN5="CIKDITIRO",VLOOKUP(A5,'BR DTG CIKDITIRO'!C:E,3,0),IF(FR_HITUNG_MINMAX!AN5="PESALAKAN",VLOOKUP(FR_HITUNG_MINMAX!A5,'BR DTG ADW'!C:E,3,0),IF(FR_HITUNG_MINMAX!AN5="PACUL",VLOOKUP(FR_HITUNG_MINMAX!A5,'BR DTG PACUL'!C:E,3,0),IF(FR_HITUNG_MINMAX!AN5="TRAYEMAN",VLOOKUP(FR_HITUNG_MINMAX!A5,'BR DTG TRAYEMAN'!C:E,3,0),"?")))),0) -> 0 | AQ5: =IF(AN5="PACUL",VLOOKUP(A5,'STOK PACUL'!C:H,6,0),IF(FR_HITUNG_MINMAX!AN5="PESALAKAN",VLOOKUP(FR_HITUNG_MINMAX!A5,'STOK PESALAKAN'!C:H,6,0),IF(FR_HITUNG_MINMAX!AN5="CIKDITIRO",VLOOKUP(FR_HITUNG_MINMAX!A5,'STOK CIKDITIRO'!C:H,6,0),IF(FR_HITUNG_MINMAX!AN5="TRAYEMAN",VLOOKUP(FR_HITUNG_MINMAX!A5,'STOK TRAYEMAN'!C:H,6,0),"?")))) -> 2 | AR5: =IFERROR(AQ5,AO5+AP5) -> 2 | AS5: =ROUNDUP(AL5/2,0) -> 1 | AT5: =COUNTIF(A:A,A5) -> 2 | AU5: =COUNTIF(AT:AT,"2")/2 -> 111
A6: 06401-KTL-700 | B6: GIR SET H.SUPRA FIT NEW/REVO 100CC ORI | C6: NOSTOK | D6: ORISIN | E6: D | F6: 211000 | G6: 1 | H6: GSM | I6: NSA | J6: 1 | K6: 1 | L6: 0 | M6: 0 | N6: 0 | O6: 0 | P6: 0 | Q6: 0 | R6: 0 | S6: 0 | T6: 0 | U6: 0 | V6: 0 | W6: 1 | X6: 1 | Y6: 0 | Z6: 0 | AA6: 0 | AB6: 0 | AC6: 0 | AD6: 0 | AE6: 0 | AF6: 0 | AG6: 0 | AH6: 0 | AI6: 1 | AJ6: 1 | AK6: 1 | AL6: 0 | AM6: 0 | AN6: PACUL | AO6: 0 | AP6: =IFERROR(IF(AN6="CIKDITIRO",VLOOKUP(A6,'BR DTG CIKDITIRO'!C:E,3,0),IF(FR_HITUNG_MINMAX!AN6="PESALAKAN",VLOOKUP(FR_HITUNG_MINMAX!A6,'BR DTG ADW'!C:E,3,0),IF(FR_HITUNG_MINMAX!AN6="PACUL",VLOOKUP(FR_HITUNG_MINMAX!A6,'BR DTG PACUL'!C:E,3,0),IF(FR_HITUNG_MINMAX!AN6="TRAYEMAN",VLOOKUP(FR_HITUNG_MINMAX!A6,'BR DTG TRAYEMAN'!C:E,3,0),"?")))),0) -> 0 | AQ6: =IF(AN6="PACUL",VLOOKUP(A6,'STOK PACUL'!C:H,6,0),IF(FR_HITUNG_MINMAX!AN6="PESALAKAN",VLOOKUP(FR_HITUNG_MINMAX!A6,'STOK PESALAKAN'!C:H,6,0),IF(FR_HITUNG_MINMAX!AN6="CIKDITIRO",VLOOKUP(FR_HITUNG_MINMAX!A6,'STOK CIKDITIRO'!C:H,6,0),IF(FR_HITUNG_MINMAX!AN6="TRAYEMAN",VLOOKUP(FR_HITUNG_MINMAX!A6,'STOK TRAYEMAN'!C:H,6,0),"?")))) -> 0 | AR6: =IFERROR(AQ6,AO6+AP6) -> 0 | AS6: =ROUNDUP(AL6/2,0) -> 0 | AT6: =COUNTIF(A:A,A6) -> 1 | AU6: =COUNTIF(AT:AT,"3")/3 -> 143
A7: 06401-KWW-900 | B7: GIR SET H.NEW REVO 110 / BLADE NEW ORI | C7: RODA | D7: ORISIN | E7: D | F7: 186000 | G7: 1 | H7: GSM | I7: NSA | J7: 1 | K7: 1 | L7: 0 | M7: 0 | N7: 0 | O7: 0 | P7: 0 | Q7: 0 | R7: 0 | S7: 0 | T7: 0 | U7: 1 | V7: 0 | W7: 0 | X7: 1 | Y7: 0 | Z7: 0 | AA7: 0 | AB7: 0 | AC7: 0 | AD7: 0 | AE7: 0 | AF7: 0 | AG7: 1 | AH7: 1 | AI7: 0 | AJ7: 0 | AK7: 1 | AL7: 1 | AM7: 1 | AN7: PACUL | AO7: 1 | AP7: =IFERROR(IF(AN7="CIKDITIRO",VLOOKUP(A7,'BR DTG CIKDITIRO'!C:E,3,0),IF(FR_HITUNG_MINMAX!AN7="PESALAKAN",VLOOKUP(FR_HITUNG_MINMAX!A7,'BR DTG ADW'!C:E,3,0),IF(FR_HITUNG_MINMAX!AN7="PACUL",VLOOKUP(FR_HITUNG_MINMAX!A7,'BR DTG PACUL'!C:E,3,0),IF(FR_HITUNG_MINMAX!AN7="TRAYEMAN",VLOOKUP(FR_HITUNG_MINMAX!A7,'BR DTG TRAYEMAN'!C:E,3,0),"?")))),0) -> 0 | AQ7: =IF(AN7="PACUL",VLOOKUP(A7,'STOK PACUL'!C:H,6,0),IF(FR_HITUNG_MINMAX!AN7="PESALAKAN",VLOOKUP(FR_HITUNG_MINMAX!A7,'STOK PESALAKAN'!C:H,6,0),IF(FR_HITUNG_MINMAX!AN7="CIKDITIRO",VLOOKUP(FR_HITUNG_MINMAX!A7,'STOK CIKDITIRO'!C:H,6,0),IF(FR_HITUNG_MINMAX!AN7="TRAYEMAN",VLOOKUP(FR_HITUNG_MINMAX!A7,'STOK TRAYEMAN'!C:H,6,0),"?")))) -> 1 | AR7: =IFERROR(AQ7,AO7+AP7) -> 1 | AS7: =ROUNDUP(AL7/2,0) -> 1 | AT7: =COUNTIF(A:A,A7) -> 2 | AU7: =COUNTIF(AT:AT,"4")/4 -> 101
A8: 06455-K59-A71 | B8: DISC PAD H.VARIO 125 NEW ESP ORI | C8: REM | D8: ORISIN | E8: D | F8: 81500 | G8: 1 | H8: NSA | I8: NSA | J8: 1 | K8: 1 | L8: 1 | M8: 0 | N8: 0 | O8: 0 | P8: 1 | Q8: 0 | R8: 0 | S8: 0 | T8: 0 | U8: 0 | V8: 0 | W8: 0 | X8: 1 | Y8: 1 | Z8: 0 | AA8: 0 | AB8: 1 | AC8: 1 | AD8: 0 | AE8: 0 | AF8: 0 | AG8: 0 | AH8: 0 | AI8: 0 | AJ8: 1 | AK8: 1 | AL8: 1 | AM8: 1 | AN8: PACUL | AO8: 0 | AP8: =IFERROR(IF(AN8="CIKDITIRO",VLOOKUP(A8,'BR DTG CIKDITIRO'!C:E,3,0),IF(FR_HITUNG_MINMAX!AN8="PESALAKAN",VLOOKUP(FR_HITUNG_MINMAX!A8,'BR DTG ADW'!C:E,3,0),IF(FR_HITUNG_MINMAX!AN8="PACUL",VLOOKUP(FR_HITUNG_MINMAX!A8,'BR DTG PACUL'!C:E,3,0),IF(FR_HITUNG_MINMAX!AN8="TRAYEMAN",VLOOKUP(FR_HITUNG_MINMAX!A8,'BR DTG TRAYEMAN'!C:E,3,0),"?")))),0) -> 0 | AQ8: =IF(AN8="PACUL",VLOOKUP(A8,'STOK PACUL'!C:H,6,0),IF(FR_HITUNG_MINMAX!AN8="PESALAKAN",VLOOKUP(FR_HITUNG_MINMAX!A8,'STOK PESALAKAN'!C:H,6,0),IF(FR_HITUNG_MINMAX!AN8="CIKDITIRO",VLOOKUP(FR_HITUNG_MINMAX!A8,'STOK CIKDITIRO'!C:H,6,0),IF(FR_HITUNG_MINMAX!AN8="TRAYEMAN",VLOOKUP(FR_HITUNG_MINMAX!A8,'STOK TRAYEMAN'!C:H,6,0),"?")))) -> 0 | AR8: =IFERROR(AQ8,AO8+AP8) -> 0 | AS8: =ROUNDUP(AL8/2,0) -> 1 | AT8: =COUNTIF(A:A,A8) -> 1 | AU8: =SUM(AU4:AU7) -> 775
A9: 06455-KR3-404 | B9: DISC PAD H.SUPRA X ORI | C9: REM | D9: ORISIN | E9: D | F9: 47500 | G9: 1 | H9: GSM | I9: NSA | J9: 3 | K9: 1 | L9: 0 | M9: 0 | N9: 0 | O9: 0 | P9: 0 | Q9: 0 | R9: 0 | S9: 0 | T9: 0 | U9: 0 | V9: 0 | W9: 1 | X9: 1 | Y9: 0 | Z9: 0 | AA9: 0 | AB9: 0 | AC9: 0 | AD9: 0 | AE9: 0 | AF9: 0 | AG9: 0 | AH9: 0 | AI9: 1 | AJ9: 1 | AK9: 1 | AL9: 1 | AM9: 1 | AN9: PACUL | AO9: 1 | AP9: =IFERROR(IF(AN9="CIKDITIRO",VLOOKUP(A9,'BR DTG CIKDITIRO'!C:E,3,0),IF(FR_HITUNG_MINMAX!AN9="PESALAKAN",VLOOKUP(FR_HITUNG_MINMAX!A9,'BR DTG ADW'!C:E,3,0),IF(FR_HITUNG_MINMAX!AN9="PACUL",VLOOKUP(FR_HITUNG_MINMAX!A9,'BR DTG PACUL'!C:E,3,0),IF(FR_HITUNG_MINMAX!AN9="TRAYEMAN",VLOOKUP(FR_HITUNG_MINMAX!A9,'BR DTG TRAYEMAN'!C:E,3,0),"?")))),0) -> 0 | AQ9: =IF(AN9="PACUL",VLOOKUP(A9,'STOK PACUL'!C:H,6,0),IF(FR_HITUNG_MINMAX!AN9="PESALAKAN",VLOOKUP(FR_HITUNG_MINMAX!A9,'STOK PESALAKAN'!C:H,6,0),IF(FR_HITUNG_MINMAX!AN9="CIKDITIRO",VLOOKUP(FR_HITUNG_MINMAX!A9,'STOK CIKDITIRO'!C:H,6,0),IF(FR_HITUNG_MINMAX!AN9="TRAYEMAN",VLOOKUP(FR_HITUNG_MINMAX!A9,'STOK TRAYEMAN'!C:H,6,0),"?")))) -> 1 | AR9: =IFERROR(AQ9,AO9+AP9) -> 1 | AS9: =ROUNDUP(AL9/2,0) -> 1 | AT9: =COUNTIF(A:A,A9) -> 3
A10: 06455-KVB-T01 | B10: DISC PAD H.VARIO TECHNO ORI | C10: REM | D10: ORISIN | E10: A | F10: 56000 | G10: 1 | H10: GSM | I10: NSA | J10: 3 | K10: 1 | L10: 3 | M10: 4 | N10: 1 | O10: 2 | P10: 5 | Q10: 3 | R10: 2 | S10: 3 | T10: 1 | U10: 2 | V10: 1 | W10: 0 | X10: 5 | Y10: 7 | Z10: 5 | AA10: 3 | AB10: 7 | AC10: 8 | AD10: 5 | AE10: 5 | AF10: 4 | AG10: 5 | AH10: 3 | AI10: 1 | AJ10: 3 | AK10: 8 | AL10: 5 | AM10: 8 | AN10: PACUL | AO10: 1 | AP10: =IFERROR(IF(AN10="CIKDITIRO",VLOOKUP(A10,'BR DTG CIKDITIRO'!C:E,3,0),IF(FR_HITUNG_MINMAX!AN10="PESALAKAN",VLOOKUP(FR_HITUNG_MINMAX!A10,'BR DTG ADW'!C:E,3,0),IF(FR_HITUNG_MINMAX!AN10="PACUL",VLOOKUP(FR_HITUNG_MINMAX!A10,'BR DTG PACUL'!C:E,3,0),IF(FR_HITUNG_MINMAX!AN10="TRAYEMAN",VLOOKUP(FR_HITUNG_MINMAX!A10,'BR DTG TRAYEMAN'!C:E,3,0),"?")))),0) -> 0 | AQ10: =IF(AN10="PACUL",VLOOKUP(A10,'STOK PACUL'!C:H,6,0),IF(FR_HITUNG_MINMAX!AN10="PESALAKAN",VLOOKUP(FR_HITUNG_MINMAX!A10,'STOK PESALAKAN'!C:H,6,0),IF(FR_HITUNG_MINMAX!AN10="CIKDITIRO",VLOOKUP(FR_HITUNG_MINMAX!A10,'STOK CIKDITIRO'!C:H,6,0),IF(FR_HITUNG_MINMAX!AN10="TRAYEMAN",VLOOKUP(FR_HITUNG_MINMAX!A10,'STOK TRAYEMAN'!C:H,6,0),"?")))) -> 1 | AR10: =IFERROR(AQ10,AO10+AP10) -> 1 | AS10: =ROUNDUP(AL10/2,0) -> 3 | AT10: =COUNTIF(A:A,A10) -> 2
A11: 06455-KWB-601 | B11: DISC PAD H.REVO ORI | C11: REM | D11: ORISIN | E11: C | F11: 50800 | G11: 1 | H11: GSM | I11: NSA | J11: 2 | K11: 1 | L11: 1 | M11: 1 | N11: 0 | O11: 1 | P11: 0 | Q11: 0 | R11: 0 | S11: 1 | T11: 0 | U11: 0 | V11: 0 | W11: 0 | X11: 1 | Y11: 2 | Z11: 1 | AA11: 1 | AB11: 1 | AC11: 0 | AD11: 0 | AE11: 1 | AF11: 1 | AG11: 1 | AH11: 0 | AI11: 0 | AJ11: 1 | AK11: 2 | AL11: 1 | AM11: 2 | AN11: PACUL | AO11: 2 | AP11: =IFERROR(IF(AN11="CIKDITIRO",VLOOKUP(A11,'BR DTG CIKDITIRO'!C:E,3,0),IF(FR_HITUNG_MINMAX!AN11="PESALAKAN",VLOOKUP(FR_HITUNG_MINMAX!A11,'BR DTG ADW'!C:E,3,0),IF(FR_HITUNG_MINMAX!AN11="PACUL",VLOOKUP(FR_HITUNG_MINMAX!A11,'BR DTG PACUL'!C:E,3,0),IF(FR_HITUNG_MINMAX!AN11="TRAYEMAN",VLOOKUP(FR_HITUNG_MINMAX!A11,'BR DTG TRAYEMAN'!C:E,3,0),"?")))),0) -> 0 | AQ11: =IF(AN11="PACUL",VLOOKUP(A11,'STOK PACUL'!C:H,6,0),IF(FR_HITUNG_MINMAX!AN11="PESALAKAN",VLOOKUP(FR_HITUNG_MINMAX!A11,'STOK PESALAKAN'!C:H,6,0),IF(FR_HITUNG_MINMAX!AN11="CIKDITIRO",VLOOKUP(FR_HITUNG_MINMAX!A11,'STOK CIKDITIRO'!C:H,6,0),IF(FR_HITUNG_MINMAX!AN11="TRAYEMAN",VLOOKUP(FR_HITUNG_MINMAX!A11,'STOK TRAYEMAN'!C:H,6,0),"?")))) -> 2 | AR11: =IFERROR(AQ11,AO11+AP11) -> 2 | AS11: =ROUNDUP(AL11/2,0) -> 1 | AT11: =COUNTIF(A:A,A11) -> 2
A12: 06535-GN5-505 | B12: KOMSTIR H.GRAND/BEAT/VARIO/PCX ORI | C12: BAUD | D12: ORISIN | E12: A | F12: 90000 | G12: 1 | H12: GSM | I12: NSA | J12: 2 | K12: 1 | L12: 1 | M12: 5 | N12: 2 | O12: 3 | P12: 0 | Q12: 2 | R12: 2 | S12: 6 | T12: 2 | U12: 3 | V12: 2 | W12: 2 | X12: 6 | Y12: 6 | Z12: 7 | AA12: 5 | AB12: 3 | AC12: 2 | AD12: 4 | AE12: 8 | AF12: 8 | AG12: 9 | AH12: 5 | AI12: 4 | AJ12: 3 | AK12: 9 | AL12: 6 | AM12: 9 | AN12: PACUL | AO12: 10 | AP12: =IFERROR(IF(AN12="CIKDITIRO",VLOOKUP(A12,'BR DTG CIKDITIRO'!C:E,3,0),IF(FR_HITUNG_MINMAX!AN12="PESALAKAN",VLOOKUP(FR_HITUNG_MINMAX!A12,'BR DTG ADW'!C:E,3,0),IF(FR_HITUNG_MINMAX!AN12="PACUL",VLOOKUP(FR_HITUNG_MINMAX!A12,'BR DTG PACUL'!C:E,3,0),IF(FR_HITUNG_MINMAX!AN12="TRAYEMAN",VLOOKUP(FR_HITUNG_MINMAX!A12,'BR DTG TRAYEMAN'!C:E,3,0),"?")))),0) -> 0 | AQ12: =IF(AN12="PACUL",VLOOKUP(A12,'STOK PACUL'!C:H,6,0),IF(FR_HITUNG_MINMAX!AN12="PESALAKAN",VLOOKUP(FR_HITUNG_MINMAX!A12,'STOK PESALAKAN'!C:H,6,0),IF(FR_HITUNG_MINMAX!AN12="CIKDITIRO",VLOOKUP(FR_HITUNG_MINMAX!A12,'STOK CIKDITIRO'!C:H,6,0),IF(FR_HITUNG_MINMAX!AN12="TRAYEMAN",VLOOKUP(FR_HITUNG_MINMAX!A12,'STOK TRAYEMAN'!C:H,6,0),"?")))) -> 10 | AR12: =IFERROR(AQ12,AO12+AP12) -> 10 | AS12: =ROUNDUP(AL12/2,0) -> 3 | AT12: =COUNTIF(A:A,A12) -> 4
A13: 08232-2MB-K2LN1 | B13: OLI MATIC H.MPX 2 0.65L | C13: CAIRAN | D13: OLIGEN | E13: A | F13: 42000 | G13: 1 | J13: 1 | K13: 1 | L13: 6 | M13: 6 | N13: 4 | O13: 5 | P13: 4 | Q13: 0 | R13: 0 | S13: 0 | T13: 3 | U13: 2 | V13: 8 | W13: 16 | X13: 16 | Y13: 12 | Z13: 10 | AA13: 9 | AB13: 9 | AC13: 4 | AD13: 0 | AE13: 0 | AF13: 3 | AG13: 2 | AH13: 10 | AI13: 24 | AJ13: 22 | AK13: 24 | AL13: 16 | AM13: 24 | AN13: PACUL | AO13: 80 | AP13: =IFERROR(IF(AN13="CIKDITIRO",VLOOKUP(A13,'BR DTG CIKDITIRO'!C:E,3,0),IF(FR_HITUNG_MINMAX!AN13="PESALAKAN",VLOOKUP(FR_HITUNG_MINMAX!A13,'BR DTG ADW'!C:E,3,0),IF(FR_HITUNG_MINMAX!AN13="PACUL",VLOOKUP(FR_HITUNG_MINMAX!A13,'BR DTG PACUL'!C:E,3,0),IF(FR_HITUNG_MINMAX!AN13="TRAYEMAN",VLOOKUP(FR_HITUNG_MINMAX!A13,'BR DTG TRAYEMAN'!C:E,3,0),"?")))),0) -> 0 | AQ13: =IF(AN13="PACUL",VLOOKUP(A13,'STOK PACUL'!C:H,6,0),IF(FR_HITUNG_MINMAX!AN13="PESALAKAN",VLOOKUP(FR_HITUNG_MINMAX!A13,'STOK PESALAKAN'!C:H,6,0),IF(FR_HITUNG_MINMAX!AN13="CIKDITIRO",VLOOKUP(FR_HITUNG_MINMAX!A13,'STOK CIKDITIRO'!C:H,6,0),IF(FR_HITUNG_MINMAX!AN13="TRAYEMAN",VLOOKUP(FR_HITUNG_MINMAX!A13,'STOK TRAYEMAN'!C:H,6,0),"?")))) -> 80 | AR13: =IFERROR(AQ13,AO13+AP13) -> 80 | AS13: =ROUNDUP(AL13/2,0) -> 8 | AT13: =COUNTIF(A:A,A13) -> 4
A14: 08232-2MB-K8JN1 | B14: OLI GEAR H.AHM 120ML | C14: CAIRAN | D14: OLIGEN | E14: A | F14: 16000 | G14: 12 | H14: HKJ | I14: NSA | J14: 14 | K14: 1 | L14: 33 | M14: 31 | N14: 28 | O14: 29 | P14: 26 | Q14: 28 | R14: 31 | S14: 33 | T14: 26 | U14: 27 | V14: 31 | W14: 24 | X14: 33 | Y14: 64 | Z14: 59 | AA14: 57 | AB14: 55 | AC14: 54 | AD14: 59 | AE14: 64 | AF14: 59 | AG14: 60 | AH14: 58 | AI14: 55 | AJ14: 57 | AK14: 64 | AL14: 33 | AM14: 64 | AN14: PACUL | AO14: 26 | AP14: =IFERROR(IF(AN14="CIKDITIRO",VLOOKUP(A14,'BR DTG CIKDITIRO'!C:E,3,0),IF(FR_HITUNG_MINMAX!AN14="PESALAKAN",VLOOKUP(FR_HITUNG_MINMAX!A14,'BR DTG ADW'!C:E,3,0),IF(FR_HITUNG_MINMAX!AN14="PACUL",VLOOKUP(FR_HITUNG_MINMAX!A14,'BR DTG PACUL'!C:E,3,0),IF(FR_HITUNG_MINMAX!AN14="TRAYEMAN",VLOOKUP(FR_HITUNG_MINMAX!A14,'BR DTG TRAYEMAN'!C:E,3,0),"?")))),0) -> 0 | AQ14: =IF(AN14="PACUL",VLOOKUP(A14,'STOK PACUL'!C:H,6,0),IF(FR_HITUNG_MINMAX!AN14="PESALAKAN",VLOOKUP(FR_HITUNG_MINMAX!A14,'STOK PESALAKAN'!C:H,6,0),IF(FR_HITUNG_MINMAX!AN14="CIKDITIRO",VLOOKUP(FR_HITUNG_MINMAX!A14,'STOK CIKDITIRO'!C:H,6,0),IF(FR_HITUNG_MINMAX!AN14="TRAYEMAN",VLOOKUP(FR_HITUNG_MINMAX!A14,'STOK TRAYEMAN'!C:H,6,0),"?")))) -> 26 | AR14: =IFERROR(AQ14,AO14+AP14) -> 26 | AS14: =ROUNDUP(AL14/2,0) -> 17 | AT14: =COUNTIF(A:A,A14) -> 4
A15: 08232-M99-K1JN1 | B15: OLI MATIC H.MPX 2 0.8L | C15: CAIRAN | D15: OLIGEN | E15: A | F15: 50150 | G15: 24 | H15: HKJ | I15: NSA | J15: 38 | K15: 1 | L15: 38 | M15: 41 | N15: 42 | O15: 48 | P15: 38 | Q15: 37 | R15: 50 | S15: 41 | T15: 34 | U15: 44 | V15: 40 | W15: 27 | X15: 50 | Y15: 79 | Z15: 83 | AA15: 90 | AB15: 86 | AC15: 75 | AD15: 87 | AE15: 91 | AF15: 75 | AG15: 85 | AH15: 84 | AI15: 67 | AJ15: 65 | AK15: 91 | AL15: 50 | AM15: 91 | AN15: PACUL | AO15: 68 | AP15: =IFERROR(IF(AN15="CIKDITIRO",VLOOKUP(A15,'BR DTG CIKDITIRO'!C:E,3,0),IF(FR_HITUNG_MINMAX!AN15="PESALAKAN",VLOOKUP(FR_HITUNG_MINMAX!A15,'BR DTG ADW'!C:E,3,0),IF(FR_HITUNG_MINMAX!AN15="PACUL",VLOOKUP(FR_HITUNG_MINMAX!A15,'BR DTG PACUL'!C:E,3,0),IF(FR_HITUNG_MINMAX!AN15="TRAYEMAN",VLOOKUP(FR_HITUNG_MINMAX!A15,'BR DTG TRAYEMAN'!C:E,3,0),"?")))),0) -> 0 | AQ15: =IF(AN15="PACUL",VLOOKUP(A15,'STOK PACUL'!C:H,6,0),IF(FR_HITUNG_MINMAX!AN15="PESALAKAN",VLOOKUP(FR_HITUNG_MINMAX!A15,'STOK PESALAKAN'!C:H,6,0),IF(FR_HITUNG_MINMAX!AN15="CIKDITIRO",VLOOKUP(FR_HITUNG_MINMAX!A15,'STOK CIKDITIRO'!C:H,6,0),IF(FR_HITUNG_MINMAX!AN15="TRAYEMAN",VLOOKUP(FR_HITUNG_MINMAX!A15,'STOK TRAYEMAN'!C:H,6,0),"?")))) -> 68 | AR15: =IFERROR(AQ15,AO15+AP15) -> 68 | AS15: =ROUNDUP(AL15/2,0) -> 25 | AT15: =COUNTIF(A:A,A15) -> 4
A16: 08232-M99-K8JN9 | B16: OLI BEBEK H.MPX 1 0.8L | C16: CAIRAN | D16: OLIGEN | E16: A | F16: 48450 | G16: 2 | H16: HKJ | I16: NSA | J16: 7 | K16: 1 | L16: 7 | M16: 5 | N16: 4 | O16: 1 | P16: 1 | Q16: 3 | R16: 1 | S16: 1 | T16: 5 | U16: 9 | V16: 0 | W16: 1 | X16: 9 | Y16: 12 | Z16: 9 | AA16: 5 | AB16: 2 | AC16: 4 | AD16: 4 | AE16: 2 | AF16: 6 | AG16: 10 | AH16: 9 | AI16: 1 | AJ16: 8 | AK16: 12 | AL16: 9 | AM16: 12 | AN16: PACUL | AO16: 8 | AP16: =IFERROR(IF(AN16="CIKDITIRO",VLOOKUP(A16,'BR DTG CIKDITIRO'!C:E,3,0),IF(FR_HITUNG_MINMAX!AN16="PESALAKAN",VLOOKUP(FR_HITUNG_MINMAX!A16,'BR DTG ADW'!C:E,3,0),IF(FR_HITUNG_MINMAX!AN16="PACUL",VLOOKUP(FR_HITUNG_MINMAX!A16,'BR DTG PACUL'!C:E,3,0),IF(FR_HITUNG_MINMAX!AN16="TRAYEMAN",VLOOKUP(FR_HITUNG_MINMAX!A16,'BR DTG TRAYEMAN'!C:E,3,0),"?")))),0) -> 0 | AQ16: =IF(AN16="PACUL",VLOOKUP(A16,'STOK PACUL'!C:H,6,0),IF(FR_HITUNG_MINMAX!AN16="PESALAKAN",VLOOKUP(FR_HITUNG_MINMAX!A16,'STOK PESALAKAN'!C:H,6,0),IF(FR_HITUNG_MINMAX!AN16="CIKDITIRO",VLOOKUP(FR_HITUNG_MINMAX!A16,'STOK CIKDITIRO'!C:H,6,0),IF(FR_HITUNG_MINMAX!AN16="TRAYEMAN",VLOOKUP(FR_HITUNG_MINMAX!A16,'STOK TRAYEMAN'!C:H,6,0),"?")))) -> 8 | AR16: =IFERROR(AQ16,AO16+AP16) -> 8 | AS16: =ROUNDUP(AL16/2,0) -> 5 | AT16: =COUNTIF(A:A,A16) -> 3
A17: 082332M99K8JNI | B17: OLI SPORT H.MPX 1 1L | C17: CAIRAN | D17: OLIGEN | E17: C | F17: 56000 | G17: 1 | H17: GSM | I17: NSA | J17: 2 | K17: 1 | L17: 0 | M17: 1 | N17: 0 | O17: 1 | P17: 1 | Q17: 0 | R17: 0 | S17: 1 | T17: 1 | U17: 0 | V17: 0 | W17: 1 | X17: 1 | Y17: 1 | Z17: 1 | AA17: 1 | AB17: 2 | AC17: 1 | AD17: 0 | AE17: 1 | AF17: 2 | AG17: 1 | AH17: 0 | AI17: 1 | AJ17: 1 | AK17: 2 | AL17: 1 | AM17: 2 | AN17: PACUL | AO17: 4 | AP17: =IFERROR(IF(AN17="CIKDITIRO",VLOOKUP(A17,'BR DTG CIKDITIRO'!C:E,3,0),IF(FR_HITUNG_MINMAX!AN17="PESALAKAN",VLOOKUP(FR_HITUNG_MINMAX!A17,'BR DTG ADW'!C:E,3,0),IF(FR_HITUNG_MINMAX!AN17="PACUL",VLOOKUP(FR_HITUNG_MINMAX!A17,'BR DTG PACUL'!C:E,3,0),IF(FR_HITUNG_MINMAX!AN17="TRAYEMAN",VLOOKUP(FR_HITUNG_MINMAX!A17,'BR DTG TRAYEMAN'!C:E,3,0),"?")))),0) -> 0 | AQ17: =IF(AN17="PACUL",VLOOKUP(A17,'STOK PACUL'!C:H,6,0),IF(FR_HITUNG_MINMAX!AN17="PESALAKAN",VLOOKUP(FR_HITUNG_MINMAX!A17,'STOK PESALAKAN'!C:H,6,0),IF(FR_HITUNG_MINMAX!AN17="CIKDITIRO",VLOOKUP(FR_HITUNG_MINMAX!A17,'STOK CIKDITIRO'!C:H,6,0),IF(FR_HITUNG_MINMAX!AN17="TRAYEMAN",VLOOKUP(FR_HITUNG_MINMAX!A17,'STOK TRAYEMAN'!C:H,6,0),"?")))) -> 4 | AR17: =IFERROR(AQ17,AO17+AP17) -> 4 | AS17: =ROUNDUP(AL17/2,0) -> 1 | AT17: =COUNTIF(A:A,A17) -> 3
A18: 08234-2MB-K8JN0 | B18: OLI MATIC H.SPX 2 0.8L | C18: CAIRAN | D18: OLIGEN | E18: A | F18: 59925 | G18: 6 | H18: HKJ | I18: NSA | J18: 14 | K18: 1 | L18: 1 | M18: 4 | N18: 3 | O18: 13 | P18: 4 | Q18: 5 | R18: 6 | S18: 2 | T18: 7 | U18: 3 | V18: 3 | W18: 7 | X18: 13 | Y18: 5 | Z18: 7 | AA18: 16 | AB18: 17 | AC18: 9 | AD18: 11 | AE18: 8 | AF18: 9 | AG18: 5 | AH18: 6 | AI18: 10 | AJ18: 8 | AK18: 17 | AL18: 13 | AM18: 17 | AN18: PACUL | AO18: 10 | AP18: =IFERROR(IF(AN18="CIKDITIRO",VLOOKUP(A18,'BR DTG CIKDITIRO'!C:E,3,0),IF(FR_HITUNG_MINMAX!AN18="PESALAKAN",VLOOKUP(FR_HITUNG_MINMAX!A18,'BR DTG ADW'!C:E,3,0),IF(FR_HITUNG_MINMAX!AN18="PACUL",VLOOKUP(FR_HITUNG_MINMAX!A18,'BR DTG PACUL'!C:E,3,0),IF(FR_HITUNG_MINMAX!AN18="TRAYEMAN",VLOOKUP(FR_HITUNG_MINMAX!A18,'BR DTG TRAYEMAN'!C:E,3,0),"?")))),0) -> 0 | AQ18: =IF(AN18="PACUL",VLOOKUP(A18,'STOK PACUL'!C:H,6,0),IF(FR_HITUNG_MINMAX!AN18="PESALAKAN",VLOOKUP(FR_HITUNG_MINMAX!A18,'STOK PESALAKAN'!C:H,6,0),IF(FR_HITUNG_MINMAX!AN18="CIKDITIRO",VLOOKUP(FR_HITUNG_MINMAX!A18,'STOK CIKDITIRO'!C:H,6,0),IF(FR_HITUNG_MINMAX!AN18="TRAYEMAN",VLOOKUP(FR_HITUNG_MINMAX!A18,'STOK TRAYEMAN'!C:H,6,0),"?")))) -> 10 | AR18: =IFERROR(AQ18,AO18+AP18) -> 10 | AS18: =ROUNDUP(AL18/2,0) -> 7 | AT18: =COUNTIF(A:A,A18) -> 4
A19: 08CLA-H50-500 | B19: COOLANT RADIATOR H.AHM ORI | C19: CAIRAN | D19: ORISIN | E19: A | F19: 18000 | G19: 12 | H19: GSM | I19: NSA | J19: 4 | K19: 1 | L19: 0 | M19: 3 | N19: 4 | O19: 10 | P19: 2 | Q19: 5 | R19: 9 | S19: 13 | T19: 5 | U19: 4 | V19: 6 | W19: 8 | X19: 13 | Y19: 3 | Z19: 7 | AA19: 14 | AB19: 12 | AC19: 7 | AD19: 14 | AE19: 22 | AF19: 18 | AG19: 17 | AH19: 10 | AI19: 14 | AJ19: 8 | AK19: 22 | AL19: 13 | AM19: 22 | AN19: PACUL | AO19: 8 | AP19: =IFERROR(IF(AN19="CIKDITIRO",VLOOKUP(A19,'BR DTG CIKDITIRO'!C:E,3,0),IF(FR_HITUNG_MINMAX!AN19="PESALAKAN",VLOOKUP(FR_HITUNG_MINMAX!A19,'BR DTG ADW'!C:E,3,0),IF(FR_HITUNG_MINMAX!AN19="PACUL",VLOOKUP(FR_HITUNG_MINMAX!A19,'BR DTG PACUL'!C:E,3,0),IF(FR_HITUNG_MINMAX!AN19="TRAYEMAN",VLOOKUP(FR_HITUNG_MINMAX!A19,'BR DTG TRAYEMAN'!C:E,3,0),"?")))),0) -> 0 | AQ19: =IF(AN19="PACUL",VLOOKUP(A19,'STOK PACUL'!C:H,6,0),IF(FR_HITUNG_MINMAX!AN19="PESALAKAN",VLOOKUP(FR_HITUNG_MINMAX!A19,'STOK PESALAKAN'!C:H,6,0),IF(FR_HITUNG_MINMAX!AN19="CIKDITIRO",VLOOKUP(FR_HITUNG_MINMAX!A19,'STOK CIKDITIRO'!C:H,6,0),IF(FR_HITUNG_MINMAX!AN19="TRAYEMAN",VLOOKUP(FR_HITUNG_MINMAX!A19,'STOK TRAYEMAN'!C:H,6,0),"?")))) -> 8 | AR19: =IFERROR(AQ19,AO19+AP19) -> 8 | AS19: =ROUNDUP(AL19/2,0) -> 7 | AT19: =COUNTIF(A:A,A19) -> 4
A20: 09355-50105L460 | B20: SELANG BENSIN S.SGP ORI | C20: KARET & SELANG | D20: ORISIN | E20: D | F20: 9000 | G20: 1 | H20: HKJ | J20: 1 | K20: 1 | L20: 0 | M20: 1 | N20: 0 | O20: 0 | P20: 0 | Q20: 0 | R20: 1 | S20: 0 | T20: 0 | U20: 0 | V20: 0 | W20: 0 | X20: 1 | Y20: 1 | Z20: 1 | AA20: 0 | AB20: 0 | AC20: 0 | AD20: 1 | AE20: 1 | AF20: 0 | AG20: 0 | AH20: 0 | AI20: 0 | AJ20: 0 | AK20: 1 | AL20: 1 | AM20: 2 | AN20: PACUL | AO20: 2 | AP20: =IFERROR(IF(AN20="CIKDITIRO",VLOOKUP(A20,'BR DTG CIKDITIRO'!C:E,3,0),IF(FR_HITUNG_MINMAX!AN20="PESALAKAN",VLOOKUP(FR_HITUNG_MINMAX!A20,'BR DTG ADW'!C:E,3,0),IF(FR_HITUNG_MINMAX!AN20="PACUL",VLOOKUP(FR_HITUNG_MINMAX!A20,'BR DTG PACUL'!C:E,3,0),IF(FR_HITUNG_MINMAX!AN20="TRAYEMAN",VLOOKUP(FR_HITUNG_MINMAX!A20,'BR DTG TRAYEMAN'!C:E,3,0),"?")))),0) -> 0 | AQ20: =IF(AN20="PACUL",VLOOKUP(A20,'STOK PACUL'!C:H,6,0),IF(FR_HITUNG_MINMAX!AN20="PESALAKAN",VLOOKUP(FR_HITUNG_MINMAX!A20,'STOK PESALAKAN'!C:H,6,0),IF(FR_HITUNG_MINMAX!AN20="CIKDITIRO",VLOOKUP(FR_HITUNG_MINMAX!A20,'STOK CIKDITIRO'!C:H,6,0),IF(FR_HITUNG_MINMAX!AN20="TRAYEMAN",VLOOKUP(FR_HITUNG_MINMAX!A20,'STOK TRAYEMAN'!C:H,6,0),"?")))) -> 2 | AR20: =IFERROR(AQ20,AO20+AP20) -> 2 | AS20: =ROUNDUP(AL20/2,0) -> 1 | AT20: =COUNTIF(A:A,A20) -> 3
A21: 09471-12008-000 | B21: BOHLAM BELAKANG SGP ORI (PS) | C21: KELISTRIKAN. STATER/ENGKOL | D21: ORISIN | E21: A | F21: 12000 | G21: 1 | J21: 1 | K21: 1 | L21: 8 | M21: 6 | N21: 1 | O21: 3 | P21: 5 | Q21: 4 | R21: 4 | S21: 3 | T21: 3 | U21: 5 | V21: 5 | W21: 3 | X21: 8 | Y21: 14 | Z21: 7 | AA21: 4 | AB21: 8 | AC21: 9 | AD21: 8 | AE21: 7 | AF21: 6 | AG21: 8 | AH21: 10 | AI21: 8 | AJ21: 11 | AK21: 14 | AL21: 8 | AM21: 14 | AN21: PACUL | AO21: 9 | AP21: =IFERROR(IF(AN21="CIKDITIRO",VLOOKUP(A21,'BR DTG CIKDITIRO'!C:E,3,0),IF(FR_HITUNG_MINMAX!AN21="PESALAKAN",VLOOKUP(FR_HITUNG_MINMAX!A21,'BR DTG ADW'!C:E,3,0),IF(FR_HITUNG_MINMAX!AN21="PACUL",VLOOKUP(FR_HITUNG_MINMAX!A21,'BR DTG PACUL'!C:E,3,0),IF(FR_HITUNG_MINMAX!AN21="TRAYEMAN",VLOOKUP(FR_HITUNG_MINMAX!A21,'BR DTG TRAYEMAN'!C:E,3,0),"?")))),0) -> 0 | AQ21: =IF(AN21="PACUL",VLOOKUP(A21,'STOK PACUL'!C:H,6,0),IF(FR_HITUNG_MINMAX!AN21="PESALAKAN",VLOOKUP(FR_HITUNG_MINMAX!A21,'STOK PESALAKAN'!C:H,6,0),IF(FR_HITUNG_MINMAX!AN21="CIKDITIRO",VLOOKUP(FR_HITUNG_MINMAX!A21,'STOK CIKDITIRO'!C:H,6,0),IF(FR_HITUNG_MINMAX!AN21="TRAYEMAN",VLOOKUP(FR_HITUNG_MINMAX!A21,'STOK TRAYEMAN'!C:H,6,0),"?")))) -> 9 | AR21: =IFERROR(AQ21,AO21+AP21) -> 9 | AS21: =ROUNDUP(AL21/2,0) -> 4 | AT21: =COUNTIF(A:A,A21) -> 4
A22: 110/90-1264J | B22: BAN LUAR BELAKANG 110/90-12 FDR | C22: RODA | D22: ORISIN | E22: C | F22: 250000 | G22: 1 | H22: HKJ | J22: 1 | K22: 1 | L22: 1 | M22: 0 | N22: 0 | O22: 1 | P22: 0 | Q22: 0 | R22: 1 | S22: 0 | T22: 0 | U22: 2 | V22: 0 | W22: 0 | X22: 2 | Y22: 1 | Z22: 0 | AA22: 1 | AB22: 1 | AC22: 0 | AD22: 1 | AE22: 1 | AF22: 0 | AG22: 2 | AH22: 2 | AI22: 0 | AJ22: 1 | AK22: 2 | AL22: 2 | AM22: 2 | AN22: PACUL | AO22: 1 | AP22: =IFERROR(IF(AN22="CIKDITIRO",VLOOKUP(A22,'BR DTG CIKDITIRO'!C:E,3,0),IF(FR_HITUNG_MINMAX!AN22="PESALAKAN",VLOOKUP(FR_HITUNG_MINMAX!A22,'BR DTG ADW'!C:E,3,0),IF(FR_HITUNG_MINMAX!AN22="PACUL",VLOOKUP(FR_HITUNG_MINMAX!A22,'BR DTG PACUL'!C:E,3,0),IF(FR_HITUNG_MINMAX!AN22="TRAYEMAN",VLOOKUP(FR_HITUNG_MINMAX!A22,'BR DTG TRAYEMAN'!C:E,3,0),"?")))),0) -> 0 | AQ22: =IF(AN22="PACUL",VLOOKUP(A22,'STOK PACUL'!C:H,6,0),IF(FR_HITUNG_MINMAX!AN22="PESALAKAN",VLOOKUP(FR_HITUNG_MINMAX!A22,'STOK PESALAKAN'!C:H,6,0),IF(FR_HITUNG_MINMAX!AN22="CIKDITIRO",VLOOKUP(FR_HITUNG_MINMAX!A22,'STOK CIKDITIRO'!C:H,6,0),IF(FR_HITUNG_MINMAX!AN22="TRAYEMAN",VLOOKUP(FR_HITUNG_MINMAX!A22,'STOK TRAYEMAN'!C:H,6,0),"?")))) -> 1 | AR22: =IFERROR(AQ22,AO22+AP22) -> 1 | AS22: =ROUNDUP(AL22/2,0) -> 1 | AT22: =COUNTIF(A:A,A22) -> 3
A23: 11103-KVB-930 | B23: KARET MONTING H.VARIO ORI | C23: KARET & SELANG | D23: ORISIN | E23: D | F23: 20750 | G23: 1 | H23: SLT | I23: NSA | J23: 1 | K23: 1 | L23: 0 | M23: 0 | N23: 0 | O23: 0 | P23: 0 | Q23: 0 | R23: 0 | S23: 0 | T23: 2 | U23: 0 | V23: 0 | W23: 0 | X23: 2 | Y23: 0 | Z23: 0 | AA23: 0 | AB23: 0 | AC23: 0 | AD23: 0 | AE23: 0 | AF23: 2 | AG23: 0 | AH23: 0 | AI23: 0 | AJ23: 0 | AK23: 2 | AL23: 2 | AM23: 2 | AN23: PACUL | AO23: 2 | AP23: =IFERROR(IF(AN23="CIKDITIRO",VLOOKUP(A23,'BR DTG CIKDITIRO'!C:E,3,0),IF(FR_HITUNG_MINMAX!AN23="PESALAKAN",VLOOKUP(FR_HITUNG_MINMAX!A23,'BR DTG ADW'!C:E,3,0),IF(FR_HITUNG_MINMAX!AN23="PACUL",VLOOKUP(FR_HITUNG_MINMAX!A23,'BR DTG PACUL'!C:E,3,0),IF(FR_HITUNG_MINMAX!AN23="TRAYEMAN",VLOOKUP(FR_HITUNG_MINMAX!A23,'BR DTG TRAYEMAN'!C:E,3,0),"?")))),0) -> 0 | AQ23: =IF(AN23="PACUL",VLOOKUP(A23,'STOK PACUL'!C:H,6,0),IF(FR_HITUNG_MINMAX!AN23="PESALAKAN",VLOOKUP(FR_HITUNG_MINMAX!A23,'STOK PESALAKAN'!C:H,6,0),IF(FR_HITUNG_MINMAX!AN23="CIKDITIRO",VLOOKUP(FR_HITUNG_MINMAX!A23,'STOK CIKDITIRO'!C:H,6,0),IF(FR_HITUNG_MINMAX!AN23="TRAYEMAN",VLOOKUP(FR_HITUNG_MINMAX!A23,'STOK TRAYEMAN'!C:H,6,0),"?")))) -> 2 | AR23: =IFERROR(AQ23,AO23+AP23) -> 2 | AS23: =ROUNDUP(AL23/2,0) -> 1 | AT23: =COUNTIF(A:A,A23) -> 1
A24: 11361-KWN-901 | B24: PLAT DUDUKAN SPULL ASSY H.VARIO ORI | D24: ORISIN | E24: D | F24: 128000 | G24: 1 | J24: 1 | K24: 1 | L24: 0 | M24: 0 | N24: 0 | O24: 1 | P24: 0 | Q24: 0 | R24: 0 | S24: 0 | T24: 0 | U24: 0 | V24: 0 | W24: 0 | X24: 1 | Y24: 0 | Z24: 0 | AA24: 1 | AB24: 1 | AC24: 0 | AD24: 0 | AE24: 0 | AF24: 0 | AG24: 0 | AH24: 0 | AI24: 0 | AJ24: 0 | AK24: 1 | AL24: 1 | AM24: 1 | AN24: PACUL | AO24: 0 | AP24: =IFERROR(IF(AN24="CIKDITIRO",VLOOKUP(A24,'BR DTG CIKDITIRO'!C:E,3,0),IF(FR_HITUNG_MINMAX!AN24="PESALAKAN",VLOOKUP(FR_HITUNG_MINMAX!A24,'BR DTG ADW'!C:E,3,0),IF(FR_HITUNG_MINMAX!AN24="PACUL",VLOOKUP(FR_HITUNG_MINMAX!A24,'BR DTG PACUL'!C:E,3,0),IF(FR_HITUNG_MINMAX!AN24="TRAYEMAN",VLOOKUP(FR_HITUNG_MINMAX!A24,'BR DTG TRAYEMAN'!C:E,3,0),"?")))),0) -> 0 | AQ24: =IF(AN24="PACUL",VLOOKUP(A24,'STOK PACUL'!C:H,6,0),IF(FR_HITUNG_MINMAX!AN24="PESALAKAN",VLOOKUP(FR_HITUNG_MINMAX!A24,'STOK PESALAKAN'!C:H,6,0),IF(FR_HITUNG_MINMAX!AN24="CIKDITIRO",VLOOKUP(FR_HITUNG_MINMAX!A24,'STOK CIKDITIRO'!C:H,6,0),IF(FR_HITUNG_MINMAX!AN24="TRAYEMAN",VLOOKUP(FR_HITUNG_MINMAX!A24,'STOK TRAYEMAN'!C:H,6,0),"?")))) -> 0 | AR24: =IFERROR(AQ24,AO24+AP24) -> 0 | AS24: =ROUNDUP(AL24/2,0) -> 1 | AT24: =COUNTIF(A:A,A24) -> 1
A25: 11363-KWN-900 | B25: ORING MAGHNET H.VARIO 125 ORI | C25: KARET & SELANG | D25: ORISIN | E25: D | F25: 14000 | G25: 1 | H25: SLT | I25: NSA | J25: 1 | K25: 1 | L25: 0 | M25: 0 | N25: 0 | O25: 1 | P25: 0 | Q25: 0 | R25: 0 | S25: 0 | T25: 0 | U25: 0 | V25: 0 | W25: 1 | X25: 1 | Y25: 0 | Z25: 0 | AA25: 1 | AB25: 1 | AC25: 0 | AD25: 0 | AE25: 0 | AF25: 0 | AG25: 0 | AH25: 0 | AI25: 1 | AJ25: 1 | AK25: 1 | AL25: 1 | AM25: 2 | AN25: PACUL | AO25: 1 | AP25: =IFERROR(IF(AN25="CIKDITIRO",VLOOKUP(A25,'BR DTG CIKDITIRO'!C:E,3,0),IF(FR_HITUNG_MINMAX!AN25="PESALAKAN",VLOOKUP(FR_HITUNG_MINMAX!A25,'BR DTG ADW'!C:E,3,0),IF(FR_HITUNG_MINMAX!AN25="PACUL",VLOOKUP(FR_HITUNG_MINMAX!A25,'BR DTG PACUL'!C:E,3,0),IF(FR_HITUNG_MINMAX!AN25="TRAYEMAN",VLOOKUP(FR_HITUNG_MINMAX!A25,'BR DTG TRAYEMAN'!C:E,3,0),"?")))),0) -> 0 | AQ25: =IF(AN25="PACUL",VLOOKUP(A25,'STOK PACUL'!C:H,6,0),IF(FR_HITUNG_MINMAX!AN25="PESALAKAN",VLOOKUP(FR_HITUNG_MINMAX!A25,'STOK PESALAKAN'!C:H,6,0),IF(FR_HITUNG_MINMAX!AN25="CIKDITIRO",VLOOKUP(FR_HITUNG_MINMAX!A25,'STOK CIKDITIRO'!C:H,6,0),IF(FR_HITUNG_MINMAX!AN25="TRAYEMAN",VLOOKUP(FR_HITUNG_MINMAX!A25,'STOK TRAYEMAN'!C:H,6,0),"?")))) -> 1 | AR25: =IFERROR(AQ25,AO25+AP25) -> 1 | AS25: =ROUNDUP(AL25/2,0) -> 1 | AT25: =COUNTIF(A:A,A25) -> 3
A26: 11395-KWB-920 | B26: PERPAK MAGNET H.REVO FI ORI | C26: NOSTOK | D26: ORISIN | E26: D | F26: 20000 | G26: 1 | J26: 1 | K26: 1 | L26: 1 | M26: 0 | N26: 0 | O26: 0 | P26: 0 | Q26: 0 | R26: 0 | S26: 0 | T26: 0 | U26: 0 | V26: 0 | W26: 0 | X26: 1 | Y26: 1 | Z26: 0 | AA26: 0 | AB26: 0 | AC26: 0 | AD26: 0 | AE26: 0 | AF26: 0 | AG26: 0 | AH26: 0 | AI26: 0 | AJ26: 1 | AK26: 1 | AL26: 0 | AM26: 0 | AN26: PACUL | AO26: 0 | AP26: =IFERROR(IF(AN26="CIKDITIRO",VLOOKUP(A26,'BR DTG CIKDITIRO'!C:E,3,0),IF(FR_HITUNG_MINMAX!AN26="PESALAKAN",VLOOKUP(FR_HITUNG_MINMAX!A26,'BR DTG ADW'!C:E,3,0),IF(FR_HITUNG_MINMAX!AN26="PACUL",VLOOKUP(FR_HITUNG_MINMAX!A26,'BR DTG PACUL'!C:E,3,0),IF(FR_HITUNG_MINMAX!AN26="TRAYEMAN",VLOOKUP(FR_HITUNG_MINMAX!A26,'BR DTG TRAYEMAN'!C:E,3,0),"?")))),0) -> 0 | AQ26: =IF(AN26="PACUL",VLOOKUP(A26,'STOK PACUL'!C:H,6,0),IF(FR_HITUNG_MINMAX!AN26="PESALAKAN",VLOOKUP(FR_HITUNG_MINMAX!A26,'STOK PESALAKAN'!C:H,6,0),IF(FR_HITUNG_MINMAX!AN26="CIKDITIRO",VLOOKUP(FR_HITUNG_MINMAX!A26,'STOK CIKDITIRO'!C:H,6,0),IF(FR_HITUNG_MINMAX!AN26="TRAYEMAN",VLOOKUP(FR_HITUNG_MINMAX!A26,'STOK TRAYEMAN'!C:H,6,0),"?")))) -> 0 | AR26: =IFERROR(AQ26,AO26+AP26) -> 0 | AS26: =ROUNDUP(AL26/2,0) -> 0 | AT26: =COUNTIF(A:A,A26) -> 1
